Workbook

Sheet Questions
B2: Question # | C2: Assessment Requirement / Question | D2: Implementation Methodology & Audit Reference | E2: Status
B3: 1 | C3: Create a calculation to compute the Availability %. Ensure the logic includes handling for missing or error values (such as nulls or #N/A) and format the final result as a percentage. Availability % = Available Hours / Contracted Hours Do not cap values at 100%. Preserve calculated result if original data produces > 100%. Return blank where numerator/denominator is missing, zero denominator, or error. | D3: Sheet 'Performance Data'!F2:F2540 Formula: =IFERROR(IF(OR(C2="",D2="",C2=0),"",D2/C2),"") Formatted as 0.00%. Uncapped (preserves values > 100%). Handles nulls, blanks, #N/A, and 0-denominators safely. | E3: VERIFIED
B4: 2 | C4: Create calculations to determine and display the Service and Band for each User by month. Use appropriate lookup or relationship-based logic to return the correct values. Exact lookup using User ID against Users source. Operational Area in Users represents Service. | D4: Sheet 'Performance Data'!G2:G2540 (Service) & H2:H2540 (Band) Service Formula: =IFERROR(INDEX(Users!$A$2:$A$310,MATCH(A2,Users!$B$2:$B$310,0)),"") Band Formula: =IFERROR(INDEX(Users!$D$2:$D$310,MATCH(A2,Users!$B$2:$B$310,0)),"") Exact match against 309 user master records. | E4: VERIFIED
B5: 3 | C5: Create a calculation that returns TRUE or FALSE to indicate whether a User belongs to Service A and has a Band 3 classification. Apply conditional logic to evaluate both criteria. | D5: Sheet 'Performance Data'!I2:I2540 Formula: =AND(G2="Service A",H2="Band 3") Returns TRUE only when both criteria are met (856 rows TRUE, 1,683 rows FALSE). | E5: VERIFIED
B6: 4 | C6: Create a formula or measure to calculate both the Average and Median Availability % for the year 2025, filtered to include only Service B and Users in Band 3 and Band 5. Expected: Average ~ 78.91%, Median ~ 85.05%, Observations ~ 796 valid rows. | D6: Sheet 'Performance Data'!J2:J2540 & 'Summary'!A7:D10 Helper Column: =IF(AND(YEAR(B2)=2025,G2="Service B",OR(H2="Band 3",H2="Band 5"),ISNUMBER(F2)),F2,"") Average Formula (Summary!B9): =IFERROR(AVERAGE('Performance Data'!$J$2:$J$2540),"") -> 78.91% Median Formula (Summary!B10): =IFERROR(MEDIAN('Performance Data'!$J$2:$J$2540),"") -> 85.05% Includes QA check section with automated PASS validation. | E6: VERIFIED
B7: 5 | C7: Create a dynamic table or summary view that displays Availability % by month for 2025, which can be controlled using filters or slicers for both Band and Service. Accompany this with an appropriate visual to enable clear and interactive comparison across Bands and Services. | D7: Sheet 'Summary'!A12:E25 & Dynamic Line Chart Powered by AVERAGEIFS formulas referencing Service (B3) and Band (B4) dropdowns. Includes 'All' options across Services (All, Service A-D) and Bands (All, Band 3-5). Excludes formula blanks correctly without denominator distortion (Jan Service B+Band 3 = 75.93%, Feb = 84.26%). Interactive chart plots monthly comparison. | E7: VERIFIED

Sheet Users
A1: Operational Area | B1: User | C1: FTE | D1: Band | E1: Start Date (US Format) | F1: Start Date (UK Format)
A2: Service A | B2: User1000 | C2: 1 | D2: Band 3 | E2: 12/1/2025 | F2: 45992
A3: Service A | B3: User1001 | C3: 1 | D3: Band 5 | E3: 9/22/2025 | F3: 45922
A4: Service B | B4: User1002 | C4: 0.8 | D4: Band 3 | E4: 10/6/2025 | F4: 45936
A5: Service C | B5: User1003 | C5: 1 | D5: Band 4 | E5: 12/1/2025 | F5: 45992
A6: Service A | B6: User1004 | C6: 1 | D6: Band 5 | E6: 9/15/2025 | F6: 45915
A7: Service B | B7: User1005 | C7: 1 | D7: Band 3 | E7: 10/6/2025 | F7: 45936
A8: Service B | B8: User1006 | C8: 1 | D8: Band 5 | E8: 11/3/2025 | F8: 45964
A9: Service B | B9: User1007 | C9: 1 | D9: Band 3 | E9: 10/6/2025 | F9: 45936
A10: Service A | B10: User1008 | C10: 1 | D10: Band 3 | E10: 12/1/2025 | F10: 45992
A11: Service B | B11: User1009 | C11: 1 | D11: Band 3 | E11: 10/1/2025 | F11: 45931
A12: Service A | B12: User1010 | C12: 0.9 | D12: Band 3 | E12: 12/2/2025 | F12: 45993
A13: Service A | B13: User1011 | C13: 0.81081081 | D13: Band 3 | E13: 9/15/2025 | F13: 45915
... A310: Service B | B310: User1308 | C310: 1 | D310: Band 5 | E310: 1/5/2026 | F310: 46027

Sheet Performance Data
A1: User | B1: Reporting Month | C1: Contracted Hours | D1: Available Hours | E1: Occupied Hours | F1: Availability % | G1: Service | H1: Band | I1: Service A & Band 3 | J1: Q4 Eligible Availability %
A2: User1000 | B2: 45992 | C2: 155.4 | D2: 0.5 | E2: 0.5 | F2: =IFERROR(IF(OR(C2="",D2="",C2=0),"",D2/C2),"") | G2: =IFERROR(INDEX(Users!$A$2:$A$310,MATCH(A2,Users!$B$2:$B$310,0)),"") | H2: =IFERROR(INDEX(Users!$D$2:$D$310,MATCH(A2,Users!$B$2:$B$310,0)),"") | I2: =AND(G2="Service A",H2="Band 3") | J2: =IF(AND(YEAR(B2)=2025,G2="Service B",OR(H2="Band 3",H2="Band 5"),ISNUMBER(F2)),F2,"")
A3: User1000 | B3: 46023 | C3: 155.4 | F3: =IFERROR(IF(OR(C3="",D3="",C3=0),"",D3/C3),"") | G3: =IFERROR(INDEX(Users!$A$2:$A$310,MATCH(A3,Users!$B$2:$B$310,0)),"") | H3: =IFERROR(INDEX(Users!$D$2:$D$310,MATCH(A3,Users!$B$2:$B$310,0)),"") | I3: =AND(G3="Service A",H3="Band 3") | J3: =IF(AND(YEAR(B3)=2025,G3="Service B",OR(H3="Band 3",H3="Band 5"),ISNUMBER(F3)),F3,"")
A4: User1001 | B4: 45901 | C4: 51.8 | D4: 14.8 | F4: =IFERROR(IF(OR(C4="",D4="",C4=0),"",D4/C4),"") | G4: =IFERROR(INDEX(Users!$A$2:$A$310,MATCH(A4,Users!$B$2:$B$310,0)),"") | H4: =IFERROR(INDEX(Users!$D$2:$D$310,MATCH(A4,Users!$B$2:$B$310,0)),"") | I4: =AND(G4="Service A",H4="Band 3") | J4: =IF(AND(YEAR(B4)=2025,G4="Service B",OR(H4="Band 3",H4="Band 5"),ISNUMBER(F4)),F4,"")
A5: User1001 | B5: 45931 | C5: 170.2 | D5: 170.7 | E5: 41 | F5: =IFERROR(IF(OR(C5="",D5="",C5=0),"",D5/C5),"") | G5: =IFERROR(INDEX(Users!$A$2:$A$310,MATCH(A5,Users!$B$2:$B$310,0)),"") | H5: =IFERROR(INDEX(Users!$D$2:$D$310,MATCH(A5,Users!$B$2:$B$310,0)),"") | I5: =AND(G5="Service A",H5="Band 3") | J5: =IF(AND(YEAR(B5)=2025,G5="Service B",OR(H5="Band 3",H5="Band 5"),ISNUMBER(F5)),F5,"")
A6: User1001 | B6: 45962 | C6: 148 | D6: 148.20333 | E6: 36.12 | F6: =IFERROR(IF(OR(C6="",D6="",C6=0),"",D6/C6),"") | G6: =IFERROR(INDEX(Users!$A$2:$A$310,MATCH(A6,Users!$B$2:$B$310,0)),"") | H6: =IFERROR(INDEX(Users!$D$2:$D$310,MATCH(A6,Users!$B$2:$B$310,0)),"") | I6: =AND(G6="Service A",H6="Band 3") | J6: =IF(AND(YEAR(B6)=2025,G6="Service B",OR(H6="Band 3",H6="Band 5"),ISNUMBER(F6)),F6,"")
A7: User1001 | B7: 45992 | C7: 155.4 | D7: 152.59667 | E7: 73.03 | F7: =IFERROR(IF(OR(C7="",D7="",C7=0),"",D7/C7),"") | G7: =IFERROR(INDEX(Users!$A$2:$A$310,MATCH(A7,Users!$B$2:$B$310,0)),"") | H7: =IFERROR(INDEX(Users!$D$2:$D$310,MATCH(A7,Users!$B$2:$B$310,0)),"") | I7: =AND(G7="Service A",H7="Band 3") | J7: =IF(AND(YEAR(B7)=2025,G7="Service B",OR(H7="Band 3",H7="Band 5"),ISNUMBER(F7)),F7,"")
A8: User1001 | B8: 46023 | C8: 155.4 | D8: 157.22 | E8: 72.32 | F8: =IFERROR(IF(OR(C8="",D8="",C8=0),"",D8/C8),"") | G8: =IFERROR(INDEX(Users!$A$2:$A$310,MATCH(A8,Users!$B$2:$B$310,0)),"") | H8: =IFERROR(INDEX(Users!$D$2:$D$310,MATCH(A8,Users!$B$2:$B$310,0)),"") | I8: =AND(G8="Service A",H8="Band 3") | J8: =IF(AND(YEAR(B8)=2025,G8="Service B",OR(H8="Band 3",H8="Band 5"),ISNUMBER(F8)),F8,"")
A9: User1002 | B9: 45931 | C9: 118.4 | D9: 126.95 | E9: 96.4 | F9: =IFERROR(IF(OR(C9="",D9="",C9=0),"",D9/C9),"") | G9: =IFERROR(INDEX(Users!$A$2:$A$310,MATCH(A9,Users!$B$2:$B$310,0)),"") | H9: =IFERROR(INDEX(Users!$D$2:$D$310,MATCH(A9,Users!$B$2:$B$310,0)),"") | I9: =AND(G9="Service A",H9="Band 3") | J9: =IF(AND(YEAR(B9)=2025,G9="Service B",OR(H9="Band 3",H9="Band 5"),ISNUMBER(F9)),F9,"")
A10: User1002 | B10: 45962 | C10: 118.4 | D10: 58.793333 | E10: 46.91 | F10: =IFERROR(IF(OR(C10="",D10="",C10=0),"",D10/C10),"") | G10: =IFERROR(INDEX(Users!$A$2:$A$310,MATCH(A10,Users!$B$2:$B$310,0)),"") | H10: =IFERROR(INDEX(Users!$D$2:$D$310,MATCH(A10,Users!$B$2:$B$310,0)),"") | I10: =AND(G10="Service A",H10="Band 3") | J10: =IF(AND(YEAR(B10)=2025,G10="Service B",OR(H10="Band 3",H10="Band 5"),ISNUMBER(F10)),F10,"")
A11: User1002 | B11: 45992 | C11: 118.4 | D11: 1.08 | E11: 1.08 | F11: =IFERROR(IF(OR(C11="",D11="",C11=0),"",D11/C11),"") | G11: =IFERROR(INDEX(Users!$A$2:$A$310,MATCH(A11,Users!$B$2:$B$310,0)),"") | H11: =IFERROR(INDEX(Users!$D$2:$D$310,MATCH(A11,Users!$B$2:$B$310,0)),"") | I11: =AND(G11="Service A",H11="Band 3") | J11: =IF(AND(YEAR(B11)=2025,G11="Service B",OR(H11="Band 3",H11="Band 5"),ISNUMBER(F11)),F11,"")
A12: User1002 | B12: 46023 | C12: 37 | D12: 13.033333 | E12: 4 | F12: =IFERROR(IF(OR(C12="",D12="",C12=0),"",D12/C12),"") | G12: =IFERROR(INDEX(Users!$A$2:$A$310,MATCH(A12,Users!$B$2:$B$310,0)),"") | H12: =IFERROR(INDEX(Users!$D$2:$D$310,MATCH(A12,Users!$B$2:$B$310,0)),"") | I12: =AND(G12="Service A",H12="Band 3") | J12: =IF(AND(YEAR(B12)=2025,G12="Service B",OR(H12="Band 3",H12="Band 5"),ISNUMBER(F12)),F12,"")
A13: User1003 | B13: 45992 | C13: 155.4 | D13: 75.016667 | E13: 0.25 | F13: =IFERROR(IF(OR(C13="",D13="",C13=0),"",D13/C13),"") | G13: =IFERROR(INDEX(Users!$A$2:$A$310,MATCH(A13,Users!$B$2:$B$310,0)),"") | H13: =IFERROR(INDEX(Users!$D$2:$D$310,MATCH(A13,Users!$B$2:$B$310,0)),"") | I13: =AND(G13="Service A",H13="Band 3") | J13: =IF(AND(YEAR(B13)=2025,G13="Service B",OR(H13="Band 3",H13="Band 5"),ISNUMBER(F13)),F13,"")
A14: User1003 | B14: 46023 | C14: 155.4 | D14: 152.05333 | E14: 15.32 | F14: =IFERROR(IF(OR(C14="",D14="",C14=0),"",D14/C14),"") | G14: =IFERROR(INDEX(Users!$A$2:$A$310,MATCH(A14,Users!$B$2:$B$310,0)),"") | H14: =IFERROR(INDEX(Users!$D$2:$D$310,MATCH(A14,Users!$B$2:$B$310,0)),"") | I14: =AND(G14="Service A",H14="Band 3") | J14: =IF(AND(YEAR(B14)=2025,G14="Service B",OR(H14="Band 3",H14="Band 5"),ISNUMBER(F14)),F14,"")
A15: User1004 | B15: 45901 | C15: 92.5 | D15: 75.38 | E15: 49.38 | F15: =IFERROR(IF(OR(C15="",D15="",C15=0),"",D15/C15),"") | G15: =IFERROR(INDEX(Users!$A$2:$A$310,MATCH(A15,Users!$B$2:$B$310,0)),"") | H15: =IFERROR(INDEX(Users!$D$2:$D$310,MATCH(A15,Users!$B$2:$B$310,0)),"") | I15: =AND(G15="Service A",H15="Band 3") | J15: =IF(AND(YEAR(B15)=2025,G15="Service B",OR(H15="Band 3",H15="Band 5"),ISNUMBER(F15)),F15,"")
A16: User1004 | B16: 45931 | C16: 166.5 | D16: 150.02 | E16: 90.27 | F16: =IFERROR(IF(OR(C16="",D16="",C16=0),"",D16/C16),"") | G16: =IFERROR(INDEX(Users!$A$2:$A$310,MATCH(A16,Users!$B$2:$B$310,0)),"") | H16: =IFERROR(INDEX(Users!$D$2:$D$310,MATCH(A16,Users!$B$2:$B$310,0)),"") | I16: =AND(G16="Service A",H16="Band 3") | J16: =IF(AND(YEAR(B16)=2025,G16="Service B",OR(H16="Band 3",H16="Band 5"),ISNUMBER(F16)),F16,"")
... A19: User1004 | B19: 46023 | C19: 148 | D19: 94.05 | E19: 59.5 | F19: =IFERROR(IF(OR(C19="",D19="",C19=0),"",D19/C19),"") | G19: =IFERROR(INDEX(Users!$A$2:$A$310,MATCH(A19,Users!$B$2:$B$310,0)),"") | H19: =IFERROR(INDEX(Users!$D$2:$D$310,MATCH(A19,Users!$B$2:$B$310,0)),"") | I19: =AND(G19="Service A",H19="Band 3") | J19: =IF(AND(YEAR(B19)=2025,G19="Service B",OR(H19="Band 3",H19="Band 5"),ISNUMBER(F19)),F19,"")
A20: User1005 | B20: 45931 | C20: 148 | D20: 117.76667 | F20: =IFERROR(IF(OR(C20="",D20="",C20=0),"",D20/C20),"") | G20: =IFERROR(INDEX(Users!$A$2:$A$310,MATCH(A20,Users!$B$2:$B$310,0)),"") | H20: =IFERROR(INDEX(Users!$D$2:$D$310,MATCH(A20,Users!$B$2:$B$310,0)),"") | I20: =AND(G20="Service A",H20="Band 3") | J20: =IF(AND(YEAR(B20)=2025,G20="Service B",OR(H20="Band 3",H20="Band 5"),ISNUMBER(F20)),F20,"")
A21: User1005 | B21: 45962 | C21: 148 | D21: 58.966667 | E21: 2.55 | F21: =IFERROR(IF(OR(C21="",D21="",C21=0),"",D21/C21),"") | G21: =IFERROR(INDEX(Users!$A$2:$A$310,MATCH(A21,Users!$B$2:$B$310,0)),"") | H21: =IFERROR(INDEX(Users!$D$2:$D$310,MATCH(A21,Users!$B$2:$B$310,0)),"") | I21: =AND(G21="Service A",H21="Band 3") | J21: =IF(AND(YEAR(B21)=2025,G21="Service B",OR(H21="Band 3",H21="Band 5"),ISNUMBER(F21)),F21,"")
A22: User1005 | B22: 45992 | C22: 155.4 | D22: 14 | E22: 14 | F22: =IFERROR(IF(OR(C22="",D22="",C22=0),"",D22/C22),"") | G22: =IFERROR(INDEX(Users!$A$2:$A$310,MATCH(A22,Users!$B$2:$B$310,0)),"") | H22: =IFERROR(INDEX(Users!$D$2:$D$310,MATCH(A22,Users!$B$2:$B$310,0)),"") | I22: =AND(G22="Service A",H22="Band 3") | J22: =IF(AND(YEAR(B22)=2025,G22="Service B",OR(H22="Band 3",H22="Band 5"),ISNUMBER(F22)),F22,"")
A23: User1005 | B23: 46023 | C23: 155.4 | D23: 150.58333 | E23: 34 | F23: =IFERROR(IF(OR(C23="",D23="",C23=0),"",D23/C23),"") | G23: =IFERROR(INDEX(Users!$A$2:$A$310,MATCH(A23,Users!$B$2:$B$310,0)),"") | H23: =IFERROR(INDEX(Users!$D$2:$D$310,MATCH(A23,Users!$B$2:$B$310,0)),"") | I23: =AND(G23="Service A",H23="Band 3") | J23: =IF(AND(YEAR(B23)=2025,G23="Service B",OR(H23="Band 3",H23="Band 5"),ISNUMBER(F23)),F23,"")
A24: User1006 | B24: 45962 | C24: 148 | F24: =IFERROR(IF(OR(C24="",D24="",C24=0),"",D24/C24),"") | G24: =IFERROR(INDEX(Users!$A$2:$A$310,MATCH(A24,Users!$B$2:$B$310,0)),"") | H24: =IFERROR(INDEX(Users!$D$2:$D$310,MATCH(A24,Users!$B$2:$B$310,0)),"") | I24: =AND(G24="Service A",H24="Band 3") | J24: =IF(AND(YEAR(B24)=2025,G24="Service B",OR(H24="Band 3",H24="Band 5"),ISNUMBER(F24)),F24,"")
A25: User1006 | B25: 45992 | C25: 155.4 | F25: =IFERROR(IF(OR(C25="",D25="",C25=0),"",D25/C25),"") | G25: =IFERROR(INDEX(Users!$A$2:$A$310,MATCH(A25,Users!$B$2:$B$310,0)),"") | H25: =IFERROR(INDEX(Users!$D$2:$D$310,MATCH(A25,Users!$B$2:$B$310,0)),"") | I25: =AND(G25="Service A",H25="Band 3") | J25: =IF(AND(YEAR(B25)=2025,G25="Service B",OR(H25="Band 3",H25="Band 5"),ISNUMBER(F25)),F25,"")
A26: User1006 | B26: 46023 | C26: 155.4 | F26: =IFERROR(IF(OR(C26="",D26="",C26=0),"",D26/C26),"") | G26: =IFERROR(INDEX(Users!$A$2:$A$310,MATCH(A26,Users!$B$2:$B$310,0)),"") | H26: =IFERROR(INDEX(Users!$D$2:$D$310,MATCH(A26,Users!$B$2:$B$310,0)),"") | I26: =AND(G26="Service A",H26="Band 3") | J26: =IF(AND(YEAR(B26)=2025,G26="Service B",OR(H26="Band 3",H26="Band 5"),ISNUMBER(F26)),F26,"")
A27: User1007 | B27: 45931 | C27: 148 | D27: 52.033333 | F27: =IFERROR(IF(OR(C27="",D27="",C27=0),"",D27/C27),"") | G27: =IFERROR(INDEX(Users!$A$2:$A$310,MATCH(A27,Users!$B$2:$B$310,0)),"") | H27: =IFERROR(INDEX(Users!$D$2:$D$310,MATCH(A27,Users!$B$2:$B$310,0)),"") | I27: =AND(G27="Service A",H27="Band 3") | J27: =IF(AND(YEAR(B27)=2025,G27="Service B",OR(H27="Band 3",H27="Band 5"),ISNUMBER(F27)),F27,"")
A28: User1007 | B28: 45962 | C28: 148 | D28: 7.9166667 | F28: =IFERROR(IF(OR(C28="",D28="",C28=0),"",D28/C28),"") | G28: =IFERROR(INDEX(Users!$A$2:$A$310,MATCH(A28,Users!$B$2:$B$310,0)),"") | H28: =IFERROR(INDEX(Users!$D$2:$D$310,MATCH(A28,Users!$B$2:$B$310,0)),"") | I28: =AND(G28="Service A",H28="Band 3") | J28: =IF(AND(YEAR(B28)=2025,G28="Service B",OR(H28="Band 3",H28="Band 5"),ISNUMBER(F28)),F28,"")
A29: User1007 | B29: 45992 | C29: 155.4 | D29: 1.25 | E29: 1.25 | F29: =IFERROR(IF(OR(C29="",D29="",C29=0),"",D29/C29),"") | G29: =IFERROR(INDEX(Users!$A$2:$A$310,MATCH(A29,Users!$B$2:$B$310,0)),"") | H29: =IFERROR(INDEX(Users!$D$2:$D$310,MATCH(A29,Users!$B$2:$B$310,0)),"") | I29: =AND(G29="Service A",H29="Band 3") | J29: =IF(AND(YEAR(B29)=2025,G29="Service B",OR(H29="Band 3",H29="Band 5"),ISNUMBER(F29)),F29,"")
A30: User1007 | B30: 46023 | C30: 155.4 | D30: 95.06 | E30: 22.31 | F30: =IFERROR(IF(OR(C30="",D30="",C30=0),"",D30/C30),"") | G30: =IFERROR(INDEX(Users!$A$2:$A$310,MATCH(A30,Users!$B$2:$B$310,0)),"") | H30: =IFERROR(INDEX(Users!$D$2:$D$310,MATCH(A30,Users!$B$2:$B$310,0)),"") | I30: =AND(G30="Service A",H30="Band 3") | J30: =IF(AND(YEAR(B30)=2025,G30="Service B",OR(H30="Band 3",H30="Band 5"),ISNUMBER(F30)),F30,"")
A31: User1008 | B31: 45992 | C31: 155.4 | D31: 81.4 | F31: =IFERROR(IF(OR(C31="",D31="",C31=0),"",D31/C31),"") | G31: =IFERROR(INDEX(Users!$A$2:$A$310,MATCH(A31,Users!$B$2:$B$310,0)),"") | H31: =IFERROR(INDEX(Users!$D$2:$D$310,MATCH(A31,Users!$B$2:$B$310,0)),"") | I31: =AND(G31="Service A",H31="Band 3") | J31: =IF(AND(YEAR(B31)=2025,G31="Service B",OR(H31="Band 3",H31="Band 5"),ISNUMBER(F31)),F31,"")
A32: User1008 | B32: 46023 | C32: 155.4 | D32: 140.6 | F32: =IFERROR(IF(OR(C32="",D32="",C32=0),"",D32/C32),"") | G32: =IFERROR(INDEX(Users!$A$2:$A$310,MATCH(A32,Users!$B$2:$B$310,0)),"") | H32: =IFERROR(INDEX(Users!$D$2:$D$310,MATCH(A32,Users!$B$2:$B$310,0)),"") | I32: =AND(G32="Service A",H32="Band 3") | J32: =IF(AND(YEAR(B32)=2025,G32="Service B",OR(H32="Band 3",H32="Band 5"),ISNUMBER(F32)),F32,"")
A33: User1009 | B33: 45901 | F33: =IFERROR(IF(OR(C33="",D33="",C33=0),"",D33/C33),"") | G33: =IFERROR(INDEX(Users!$A$2:$A$310,MATCH(A33,Users!$B$2:$B$310,0)),"") | H33: =IFERROR(INDEX(Users!$D$2:$D$310,MATCH(A33,Users!$B$2:$B$310,0)),"") | I33: =AND(G33="Service A",H33="Band 3") | J33: =IF(AND(YEAR(B33)=2025,G33="Service B",OR(H33="Band 3",H33="Band 5"),ISNUMBER(F33)),F33,"")
A34: User1009 | B34: 45931 | C34: 166.5 | F34: =IFERROR(IF(OR(C34="",D34="",C34=0),"",D34/C34),"") | G34: =IFERROR(INDEX(Users!$A$2:$A$310,MATCH(A34,Users!$B$2:$B$310,0)),"") | H34: =IFERROR(INDEX(Users!$D$2:$D$310,MATCH(A34,Users!$B$2:$B$310,0)),"") | I34: =AND(G34="Service A",H34="Band 3") | J34: =IF(AND(YEAR(B34)=2025,G34="Service B",OR(H34="Band 3",H34="Band 5"),ISNUMBER(F34)),F34,"")
A35: User1009 | B35: 45962 | C35: 148 | D35: 56.781111 | F35: =IFERROR(IF(OR(C35="",D35="",C35=0),"",D35/C35),"") | G35: =IFERROR(INDEX(Users!$A$2:$A$310,MATCH(A35,Users!$B$2:$B$310,0)),"") | H35: =IFERROR(INDEX(Users!$D$2:$D$310,MATCH(A35,Users!$B$2:$B$310,0)),"") | I35: =AND(G35="Service A",H35="Band 3") | J35: =IF(AND(YEAR(B35)=2025,G35="Service B",OR(H35="Band 3",H35="Band 5"),ISNUMBER(F35)),F35,"")
A36: User1009 | B36: 45992 | C36: 166.5 | D36: 1.42 | E36: 1.42 | F36: =IFERROR(IF(OR(C36="",D36="",C36=0),"",D36/C36),"") | G36: =IFERROR(INDEX(Users!$A$2:$A$310,MATCH(A36,Users!$B$2:$B$310,0)),"") | H36: =IFERROR(INDEX(Users!$D$2:$D$310,MATCH(A36,Users!$B$2:$B$310,0)),"") | I36: =AND(G36="Service A",H36="Band 3") | J36: =IF(AND(YEAR(B36)=2025,G36="Service B",OR(H36="Band 3",H36="Band 5"),ISNUMBER(F36)),F36,"")
A37: User1009 | B37: 46023 | C37: 148 | D37: 2.53 | E37: 2.53 | F37: =IFERROR(IF(OR(C37="",D37="",C37=0),"",D37/C37),"") | G37: =IFERROR(INDEX(Users!$A$2:$A$310,MATCH(A37,Users!$B$2:$B$310,0)),"") | H37: =IFERROR(INDEX(Users!$D$2:$D$310,MATCH(A37,Users!$B$2:$B$310,0)),"") | I37: =AND(G37="Service A",H37="Band 3") | J37: =IF(AND(YEAR(B37)=2025,G37="Service B",OR(H37="Band 3",H37="Band 5"),ISNUMBER(F37)),F37,"")
A38: User1010 | B38: 45992 | C38: 133.2 | F38: =IFERROR(IF(OR(C38="",D38="",C38=0),"",D38/C38),"") | G38: =IFERROR(INDEX(Users!$A$2:$A$310,MATCH(A38,Users!$B$2:$B$310,0)),"") | H38: =IFERROR(INDEX(Users!$D$2:$D$310,MATCH(A38,Users!$B$2:$B$310,0)),"") | I38: =AND(G38="Service A",H38="Band 3") | J38: =IF(AND(YEAR(B38)=2025,G38="Service B",OR(H38="Band 3",H38="Band 5"),ISNUMBER(F38)),F38,"")
A39: User1010 | B39: 46023 | C39: 140.6 | F39: =IFERROR(IF(OR(C39="",D39="",C39=0),"",D39/C39),"") | G39: =IFERROR(INDEX(Users!$A$2:$A$310,MATCH(A39,Users!$B$2:$B$310,0)),"") | H39: =IFERROR(INDEX(Users!$D$2:$D$310,MATCH(A39,Users!$B$2:$B$310,0)),"") | I39: =AND(G39="Service A",H39="Band 3") | J39: =IF(AND(YEAR(B39)=2025,G39="Service B",OR(H39="Band 3",H39="Band 5"),ISNUMBER(F39)),F39,"")
A40: User1011 | B40: 45901 | C40: 76 | D40: 72.903333 | E40: 57.07 | F40: =IFERROR(IF(OR(C40="",D40="",C40=0),"",D40/C40),"") | G40: =IFERROR(INDEX(Users!$A$2:$A$310,MATCH(A40,Users!$B$2:$B$310,0)),"") | H40: =IFERROR(INDEX(Users!$D$2:$D$310,MATCH(A40,Users!$B$2:$B$310,0)),"") | I40: =AND(G40="Service A",H40="Band 3") | J40: =IF(AND(YEAR(B40)=2025,G40="Service B",OR(H40="Band 3",H40="Band 5"),ISNUMBER(F40)),F40,"")
A41: User1011 | B41: 45931 | C41: 134 | D41: 119.17667 | E41: 87.01 | F41: =IFERROR(IF(OR(C41="",D41="",C41=0),"",D41/C41),"") | G41: =IFERROR(INDEX(Users!$A$2:$A$310,MATCH(A41,Users!$B$2:$B$310,0)),"") | H41: =IFERROR(INDEX(Users!$D$2:$D$310,MATCH(A41,Users!$B$2:$B$310,0)),"") | I41: =AND(G41="Service A",H41="Band 3") | J41: =IF(AND(YEAR(B41)=2025,G41="Service B",OR(H41="Band 3",H41="Band 5"),ISNUMBER(F41)),F41,"")
A42: User1011 | B42: 45962 | C42: 120 | D42: 107.5 | E42: 87.5 | F42: =IFERROR(IF(OR(C42="",D42="",C42=0),"",D42/C42),"") | G42: =IFERROR(INDEX(Users!$A$2:$A$310,MATCH(A42,Users!$B$2:$B$310,0)),"") | H42: =IFERROR(INDEX(Users!$D$2:$D$310,MATCH(A42,Users!$B$2:$B$310,0)),"") | I42: =AND(G42="Service A",H42="Band 3") | J42: =IF(AND(YEAR(B42)=2025,G42="Service B",OR(H42="Band 3",H42="Band 5"),ISNUMBER(F42)),F42,"")
...

Sheet Summary
A1: Data Analyst Practical Assessment — Executive Performance Dashboard (2025)
A3: Service Filter: | B3: Service B | D3: Instructions: | E3: Select Service / Band dropdowns to dynamically update monthly trends & chart.
A4: Band Filter: | B4: Band 3 | D4: Chart Comparison: | E4: Compares selected segment against Service benchmark, Band benchmark & Overall org.
A7: Question 4 — Benchmark QA & Validation (2025 | Service B | Band 3 & Band 5)
A8: Metric | B8: Calculated Result (Formula) | C8: Expected Target | D8: QA Status
A9: Average Availability % | B9: =IFERROR(AVERAGE('Performance Data'!$J$2:$J$2540),"") | C9: 0.7891 | D9: =IF(ISNUMBER(B9),IF(ROUND(B9,4)=ROUND(C9,4),"PASS","FAIL"),"FAIL")
A10: Median Availability % | B10: =IFERROR(MEDIAN('Performance Data'!$J$2:$J$2540),"") | C10: 0.8505 | D10: =IF(ISNUMBER(B10),IF(ROUND(B10,4)=ROUND(C10,4),"PASS","FAIL"),"FAIL")
A12: Question 5 — Dynamic 2025 Monthly Availability Summary & Benchmark Comparison
A13: Month | B13: Selected Service + Band | C13: Selected Service (all Bands) | D13: Selected Band (all Services) | E13: Overall Organisation
A14: 45658 | B14: =IFERROR(IF(AND($B$3="All",$B$4="All"),AVERAGEIFS('Performance Data'!$F$2:$F$2540,'Performance Data'!$B$2:$B$2540,$A14),IF($B$3="All",AVERAGEIFS('Performance Data'!$F$2:$F$2540,'Performance Data'!$B$2:$B$2540,$A14,'Performance Data'!$H$2:$H$2540,$B$4),IF($B$4="All",AVERAGEIFS('Performance Data'!$F$2:$F$2540,'Performance Data'!$B$2:$B$2540,$A14,'Performance Data'!$G$2:$G$2540,$B$3),AVERAGEIFS('Performance Data'!$F$2:$F$2540,'Performance Data'!$B$2:$B$2540,$A14,'Performance Data'!$G$2:$G$2540,$B$3,'Performance Data'!$H$2:$H$2540,$B$4)))),"") | C14: =IFERROR(IF($B$3="All",AVERAGEIFS('Performance Data'!$F$2:$F$2540,'Performance Data'!$B$2:$B$2540,$A14),AVERAGEIFS('Performance Data'!$F$2:$F$2540,'Performance Data'!$B$2:$B$2540,$A14,'Performance Data'!$G$2:$G$2540,$B$3)),"") | D14: =IFERROR(IF($B$4="All",AVERAGEIFS('Performance Data'!$F$2:$F$2540,'Performance Data'!$B$2:$B$2540,$A14),AVERAGEIFS('Performance Data'!$F$2:$F$2540,'Performance Data'!$B$2:$B$2540,$A14,'Performance Data'!$H$2:$H$2540,$B$4)),"") | E14: =IFERROR(AVERAGEIFS('Performance Data'!$F$2:$F$2540,'Performance Data'!$B$2:$B$2540,$A14),"")
A15: 45689 | B15: =IFERROR(IF(AND($B$3="All",$B$4="All"),AVERAGEIFS('Performance Data'!$F$2:$F$2540,'Performance Data'!$B$2:$B$2540,$A15),IF($B$3="All",AVERAGEIFS('Performance Data'!$F$2:$F$2540,'Performance Data'!$B$2:$B$2540,$A15,'Performance Data'!$H$2:$H$2540,$B$4),IF($B$4="All",AVERAGEIFS('Performance Data'!$F$2:$F$2540,'Performance Data'!$B$2:$B$2540,$A15,'Performance Data'!$G$2:$G$2540,$B$3),AVERAGEIFS('Performance Data'!$F$2:$F$2540,'Performance Data'!$B$2:$B$2540,$A15,'Performance Data'!$G$2:$G$2540,$B$3,'Performance Data'!$H$2:$H$2540,$B$4)))),"") | C15: =IFERROR(IF($B$3="All",AVERAGEIFS('Performance Data'!$F$2:$F$2540,'Performance Data'!$B$2:$B$2540,$A15),AVERAGEIFS('Performance Data'!$F$2:$F$2540,'Performance Data'!$B$2:$B$2540,$A15,'Performance Data'!$G$2:$G$2540,$B$3)),"") | D15: =IFERROR(IF($B$4="All",AVERAGEIFS('Performance Data'!$F$2:$F$2540,'Performance Data'!$B$2:$B$2540,$A15),AVERAGEIFS('Performance Data'!$F$2:$F$2540,'Performance Data'!$B$2:$B$2540,$A15,'Performance Data'!$H$2:$H$2540,$B$4)),"") | E15: =IFERROR(AVERAGEIFS('Performance Data'!$F$2:$F$2540,'Performance Data'!$B$2:$B$2540,$A15),"")
A16: 45717 | B16: =IFERROR(IF(AND($B$3="All",$B$4="All"),AVERAGEIFS('Performance Data'!$F$2:$F$2540,'Performance Data'!$B$2:$B$2540,$A16),IF($B$3="All",AVERAGEIFS('Performance Data'!$F$2:$F$2540,'Performance Data'!$B$2:$B$2540,$A16,'Performance Data'!$H$2:$H$2540,$B$4),IF($B$4="All",AVERAGEIFS('Performance Data'!$F$2:$F$2540,'Performance Data'!$B$2:$B$2540,$A16,'Performance Data'!$G$2:$G$2540,$B$3),AVERAGEIFS('Performance Data'!$F$2:$F$2540,'Performance Data'!$B$2:$B$2540,$A16,'Performance Data'!$G$2:$G$2540,$B$3,'Performance Data'!$H$2:$H$2540,$B$4)))),"") | C16: =IFERROR(IF($B$3="All",AVERAGEIFS('Performance Data'!$F$2:$F$2540,'Performance Data'!$B$2:$B$2540,$A16),AVERAGEIFS('Performance Data'!$F$2:$F$2540,'Performance Data'!$B$2:$B$2540,$A16,'Performance Data'!$G$2:$G$2540,$B$3)),"") | D16: =IFERROR(IF($B$4="All",AVERAGEIFS('Performance Data'!$F$2:$F$2540,'Performance Data'!$B$2:$B$2540,$A16),AVERAGEIFS('Performance Data'!$F$2:$F$2540,'Performance Data'!$B$2:$B$2540,$A16,'Performance Data'!$H$2:$H$2540,$B$4)),"") | E16: =IFERROR(AVERAGEIFS('Performance Data'!$F$2:$F$2540,'Performance Data'!$B$2:$B$2540,$A16),"")
A17: 45748 | B17: =IFERROR(IF(AND($B$3="All",$B$4="All"),AVERAGEIFS('Performance Data'!$F$2:$F$2540,'Performance Data'!$B$2:$B$2540,$A17),IF($B$3="All",AVERAGEIFS('Performance Data'!$F$2:$F$2540,'Performance Data'!$B$2:$B$2540,$A17,'Performance Data'!$H$2:$H$2540,$B$4),IF($B$4="All",AVERAGEIFS('Performance Data'!$F$2:$F$2540,'Performance Data'!$B$2:$B$2540,$A17,'Performance Data'!$G$2:$G$2540,$B$3),AVERAGEIFS('Performance Data'!$F$2:$F$2540,'Performance Data'!$B$2:$B$2540,$A17,'Performance Data'!$G$2:$G$2540,$B$3,'Performance Data'!$H$2:$H$2540,$B$4)))),"") | C17: =IFERROR(IF($B$3="All",AVERAGEIFS('Performance Data'!$F$2:$F$2540,'Performance Data'!$B$2:$B$2540,$A17),AVERAGEIFS('Performance Data'!$F$2:$F$2540,'Performance Data'!$B$2:$B$2540,$A17,'Performance Data'!$G$2:$G$2540,$B$3)),"") | D17: =IFERROR(IF($B$4="All",AVERAGEIFS('Performance Data'!$F$2:$F$2540,'Performance Data'!$B$2:$B$2540,$A17),AVERAGEIFS('Performance Data'!$F$2:$F$2540,'Performance Data'!$B$2:$B$2540,$A17,'Performance Data'!$H$2:$H$2540,$B$4)),"") | E17: =IFERROR(AVERAGEIFS('Performance Data'!$F$2:$F$2540,'Performance Data'!$B$2:$B$2540,$A17),"")
A18: 45778 | B18: =IFERROR(IF(AND($B$3="All",$B$4="All"),AVERAGEIFS('Performance Data'!$F$2:$F$2540,'Performance Data'!$B$2:$B$2540,$A18),IF($B$3="All",AVERAGEIFS('Performance Data'!$F$2:$F$2540,'Performance Data'!$B$2:$B$2540,$A18,'Performance Data'!$H$2:$H$2540,$B$4),IF($B$4="All",AVERAGEIFS('Performance Data'!$F$2:$F$2540,'Performance Data'!$B$2:$B$2540,$A18,'Performance Data'!$G$2:$G$2540,$B$3),AVERAGEIFS('Performance Data'!$F$2:$F$2540,'Performance Data'!$B$2:$B$2540,$A18,'Performance Data'!$G$2:$G$2540,$B$3,'Performance Data'!$H$2:$H$2540,$B$4)))),"") | C18: =IFERROR(IF($B$3="All",AVERAGEIFS('Performance Data'!$F$2:$F$2540,'Performance Data'!$B$2:$B$2540,$A18),AVERAGEIFS('Performance Data'!$F$2:$F$2540,'Performance Data'!$B$2:$B$2540,$A18,'Performance Data'!$G$2:$G$2540,$B$3)),"") | D18: =IFERROR(IF($B$4="All",AVERAGEIFS('Performance Data'!$F$2:$F$2540,'Performance Data'!$B$2:$B$2540,$A18),AVERAGEIFS('Performance Data'!$F$2:$F$2540,'Performance Data'!$B$2:$B$2540,$A18,'Performance Data'!$H$2:$H$2540,$B$4)),"") | E18: =IFERROR(AVERAGEIFS('Performance Data'!$F$2:$F$2540,'Performance Data'!$B$2:$B$2540,$A18),"")
A19: 45809 | B19: =IFERROR(IF(AND($B$3="All",$B$4="All"),AVERAGEIFS('Performance Data'!$F$2:$F$2540,'Performance Data'!$B$2:$B$2540,$A19),IF($B$3="All",AVERAGEIFS('Performance Data'!$F$2:$F$2540,'Performance Data'!$B$2:$B$2540,$A19,'Performance Data'!$H$2:$H$2540,$B$4),IF($B$4="All",AVERAGEIFS('Performance Data'!$F$2:$F$2540,'Performance Data'!$B$2:$B$2540,$A19,'Performance Data'!$G$2:$G$2540,$B$3),AVERAGEIFS('Performance Data'!$F$2:$F$2540,'Performance Data'!$B$2:$B$2540,$A19,'Performance Data'!$G$2:$G$2540,$B$3,'Performance Data'!$H$2:$H$2540,$B$4)))),"") | C19: =IFERROR(IF($B$3="All",AVERAGEIFS('Performance Data'!$F$2:$F$2540,'Performance Data'!$B$2:$B$2540,$A19),AVERAGEIFS('Performance Data'!$F$2:$F$2540,'Performance Data'!$B$2:$B$2540,$A19,'Performance Data'!$G$2:$G$2540,$B$3)),"") | D19: =IFERROR(IF($B$4="All",AVERAGEIFS('Performance Data'!$F$2:$F$2540,'Performance Data'!$B$2:$B$2540,$A19),AVERAGEIFS('Performance Data'!$F$2:$F$2540,'Performance Data'!$B$2:$B$2540,$A19,'Performance Data'!$H$2:$H$2540,$B$4)),"") | E19: =IFERROR(AVERAGEIFS('Performance Data'!$F$2:$F$2540,'Performance Data'!$B$2:$B$2540,$A19),"")
A20: 45839 | B20: =IFERROR(IF(AND($B$3="All",$B$4="All"),AVERAGEIFS('Performance Data'!$F$2:$F$2540,'Performance Data'!$B$2:$B$2540,$A20),IF($B$3="All",AVERAGEIFS('Performance Data'!$F$2:$F$2540,'Performance Data'!$B$2:$B$2540,$A20,'Performance Data'!$H$2:$H$2540,$B$4),IF($B$4="All",AVERAGEIFS('Performance Data'!$F$2:$F$2540,'Performance Data'!$B$2:$B$2540,$A20,'Performance Data'!$G$2:$G$2540,$B$3),AVERAGEIFS('Performance Data'!$F$2:$F$2540,'Performance Data'!$B$2:$B$2540,$A20,'Performance Data'!$G$2:$G$2540,$B$3,'Performance Data'!$H$2:$H$2540,$B$4)))),"") | C20: =IFERROR(IF($B$3="All",AVERAGEIFS('Performance Data'!$F$2:$F$2540,'Performance Data'!$B$2:$B$2540,$A20),AVERAGEIFS('Performance Data'!$F$2:$F$2540,'Performance Data'!$B$2:$B$2540,$A20,'Performance Data'!$G$2:$G$2540,$B$3)),"") | D20: =IFERROR(IF($B$4="All",AVERAGEIFS('Performance Data'!$F$2:$F$2540,'Performance Data'!$B$2:$B$2540,$A20),AVERAGEIFS('Performance Data'!$F$2:$F$2540,'Performance Data'!$B$2:$B$2540,$A20,'Performance Data'!$H$2:$H$2540,$B$4)),"") | E20: =IFERROR(AVERAGEIFS('Performance Data'!$F$2:$F$2540,'Performance Data'!$B$2:$B$2540,$A20),"")
A21: 45870 | B21: =IFERROR(IF(AND($B$3="All",$B$4="All"),AVERAGEIFS('Performance Data'!$F$2:$F$2540,'Performance Data'!$B$2:$B$2540,$A21),IF($B$3="All",AVERAGEIFS('Performance Data'!$F$2:$F$2540,'Performance Data'!$B$2:$B$2540,$A21,'Performance Data'!$H$2:$H$2540,$B$4),IF($B$4="All",AVERAGEIFS('Performance Data'!$F$2:$F$2540,'Performance Data'!$B$2:$B$2540,$A21,'Performance Data'!$G$2:$G$2540,$B$3),AVERAGEIFS('Performance Data'!$F$2:$F$2540,'Performance Data'!$B$2:$B$2540,$A21,'Performance Data'!$G$2:$G$2540,$B$3,'Performance Data'!$H$2:$H$2540,$B$4)))),"") | C21: =IFERROR(IF($B$3="All",AVERAGEIFS('Performance Data'!$F$2:$F$2540,'Performance Data'!$B$2:$B$2540,$A21),AVERAGEIFS('Performance Data'!$F$2:$F$2540,'Performance Data'!$B$2:$B$2540,$A21,'Performance Data'!$G$2:$G$2540,$B$3)),"") | D21: =IFERROR(IF($B$4="All",AVERAGEIFS('Performance Data'!$F$2:$F$2540,'Performance Data'!$B$2:$B$2540,$A21),AVERAGEIFS('Performance Data'!$F$2:$F$2540,'Performance Data'!$B$2:$B$2540,$A21,'Performance Data'!$H$2:$H$2540,$B$4)),"") | E21: =IFERROR(AVERAGEIFS('Performance Data'!$F$2:$F$2540,'Performance Data'!$B$2:$B$2540,$A21),"")
A22: 45901 | B22: =IFERROR(IF(AND($B$3="All",$B$4="All"),AVERAGEIFS('Performance Data'!$F$2:$F$2540,'Performance Data'!$B$2:$B$2540,$A22),IF($B$3="All",AVERAGEIFS('Performance Data'!$F$2:$F$2540,'Performance Data'!$B$2:$B$2540,$A22,'Performance Data'!$H$2:$H$2540,$B$4),IF($B$4="All",AVERAGEIFS('Performance Data'!$F$2:$F$2540,'Performance Data'!$B$2:$B$2540,$A22,'Performance Data'!$G$2:$G$2540,$B$3),AVERAGEIFS('Performance Data'!$F$2:$F$2540,'Performance Data'!$B$2:$B$2540,$A22,'Performance Data'!$G$2:$G$2540,$B$3,'Performance Data'!$H$2:$H$2540,$B$4)))),"") | C22: =IFERROR(IF($B$3="All",AVERAGEIFS('Performance Data'!$F$2:$F$2540,'Performance Data'!$B$2:$B$2540,$A22),AVERAGEIFS('Performance Data'!$F$2:$F$2540,'Performance Data'!$B$2:$B$2540,$A22,'Performance Data'!$G$2:$G$2540,$B$3)),"") | D22: =IFERROR(IF($B$4="All",AVERAGEIFS('Performance Data'!$F$2:$F$2540,'Performance Data'!$B$2:$B$2540,$A22),AVERAGEIFS('Performance Data'!$F$2:$F$2540,'Performance Data'!$B$2:$B$2540,$A22,'Performance Data'!$H$2:$H$2540,$B$4)),"") | E22: =IFERROR(AVERAGEIFS('Performance Data'!$F$2:$F$2540,'Performance Data'!$B$2:$B$2540,$A22),"")
A23: 45931 | B23: =IFERROR(IF(AND($B$3="All",$B$4="All"),AVERAGEIFS('Performance Data'!$F$2:$F$2540,'Performance Data'!$B$2:$B$2540,$A23),IF($B$3="All",AVERAGEIFS('Performance Data'!$F$2:$F$2540,'Performance Data'!$B$2:$B$2540,$A23,'Performance Data'!$H$2:$H$2540,$B$4),IF($B$4="All",AVERAGEIFS('Performance Data'!$F$2:$F$2540,'Performance Data'!$B$2:$B$2540,$A23,'Performance Data'!$G$2:$G$2540,$B$3),AVERAGEIFS('Performance Data'!$F$2:$F$2540,'Performance Data'!$B$2:$B$2540,$A23,'Performance Data'!$G$2:$G$2540,$B$3,'Performance Data'!$H$2:$H$2540,$B$4)))),"") | C23: =IFERROR(IF($B$3="All",AVERAGEIFS('Performance Data'!$F$2:$F$2540,'Performance Data'!$B$2:$B$2540,$A23),AVERAGEIFS('Performance Data'!$F$2:$F$2540,'Performance Data'!$B$2:$B$2540,$A23,'Performance Data'!$G$2:$G$2540,$B$3)),"") | D23: =IFERROR(IF($B$4="All",AVERAGEIFS('Performance Data'!$F$2:$F$2540,'Performance Data'!$B$2:$B$2540,$A23),AVERAGEIFS('Performance Data'!$F$2:$F$2540,'Performance Data'!$B$2:$B$2540,$A23,'Performance Data'!$H$2:$H$2540,$B$4)),"") | E23: =IFERROR(AVERAGEIFS('Performance Data'!$F$2:$F$2540,'Performance Data'!$B$2:$B$2540,$A23),"")
A24: 45962 | B24: =IFERROR(IF(AND($B$3="All",$B$4="All"),AVERAGEIFS('Performance Data'!$F$2:$F$2540,'Performance Data'!$B$2:$B$2540,$A24),IF($B$3="All",AVERAGEIFS('Performance Data'!$F$2:$F$2540,'Performance Data'!$B$2:$B$2540,$A24,'Performance Data'!$H$2:$H$2540,$B$4),IF($B$4="All",AVERAGEIFS('Performance Data'!$F$2:$F$2540,'Performance Data'!$B$2:$B$2540,$A24,'Performance Data'!$G$2:$G$2540,$B$3),AVERAGEIFS('Performance Data'!$F$2:$F$2540,'Performance Data'!$B$2:$B$2540,$A24,'Performance Data'!$G$2:$G$2540,$B$3,'Performance Data'!$H$2:$H$2540,$B$4)))),"") | C24: =IFERROR(IF($B$3="All",AVERAGEIFS('Performance Data'!$F$2:$F$2540,'Performance Data'!$B$2:$B$2540,$A24),AVERAGEIFS('Performance Data'!$F$2:$F$2540,'Performance Data'!$B$2:$B$2540,$A24,'Performance Data'!$G$2:$G$2540,$B$3)),"") | D24: =IFERROR(IF($B$4="All",AVERAGEIFS('Performance Data'!$F$2:$F$2540,'Performance Data'!$B$2:$B$2540,$A24),AVERAGEIFS('Performance Data'!$F$2:$F$2540,'Performance Data'!$B$2:$B$2540,$A24,'Performance Data'!$H$2:$H$2540,$B$4)),"") | E24: =IFERROR(AVERAGEIFS('Performance Data'!$F$2:$F$2540,'Performance Data'!$B$2:$B$2540,$A24),"")
A25: 45992 | B25: =IFERROR(IF(AND($B$3="All",$B$4="All"),AVERAGEIFS('Performance Data'!$F$2:$F$2540,'Performance Data'!$B$2:$B$2540,$A25),IF($B$3="All",AVERAGEIFS('Performance Data'!$F$2:$F$2540,'Performance Data'!$B$2:$B$2540,$A25,'Performance Data'!$H$2:$H$2540,$B$4),IF($B$4="All",AVERAGEIFS('Performance Data'!$F$2:$F$2540,'Performance Data'!$B$2:$B$2540,$A25,'Performance Data'!$G$2:$G$2540,$B$3),AVERAGEIFS('Performance Data'!$F$2:$F$2540,'Performance Data'!$B$2:$B$2540,$A25,'Performance Data'!$G$2:$G$2540,$B$3,'Performance Data'!$H$2:$H$2540,$B$4)))),"") | C25: =IFERROR(IF($B$3="All",AVERAGEIFS('Performance Data'!$F$2:$F$2540,'Performance Data'!$B$2:$B$2540,$A25),AVERAGEIFS('Performance Data'!$F$2:$F$2540,'Performance Data'!$B$2:$B$2540,$A25,'Performance Data'!$G$2:$G$2540,$B$3)),"") | D25: =IFERROR(IF($B$4="All",AVERAGEIFS('Performance Data'!$F$2:$F$2540,'Performance Data'!$B$2:$B$2540,$A25),AVERAGEIFS('Performance Data'!$F$2:$F$2540,'Performance Data'!$B$2:$B$2540,$A25,'Performance Data'!$H$2:$H$2540,$B$4)),"") | E25: =IFERROR(AVERAGEIFS('Performance Data'!$F$2:$F$2540,'Performance Data'!$B$2:$B$2540,$A25),"")
