Workbook

Sheet Questions
B2: Question # | C2: Question | D2: Solution / Evidence
B3: 1 | C3: Create a calculation to compute the Availability %. Ensure the logic includes handling for missing or error values (such as nulls or #N/A) and format the final result as a percentage. | D3: Performance Data!F2:F2540 – error-safe Available Hours ÷ Contracted Hours; formatted as %.
B4: 2 | C4: Create calculations to determine and display the Service and Band for each User by month. Use appropriate lookup or relationship-based logic to return the correct values. | D4: Performance Data!G:H – INDEX/MATCH lookup from Users for Service and Band.
B5: 3 | C5: Create a calculation that returns TRUE or FALSE to indicate whether a User belongs to Service A and has a Band 3 classification. Apply conditional logic to evaluate both criteria. | D5: Performance Data!I:I – AND(Service="Service A", Band="Band 3").
B6: 4 | C6: Create a formula or measure to calculate both the Average and Median Availability % for the year 2025, filtered to include only Service B and Users in Band 3 and Band 5. | D6: Performance Data!J:J + Summary!A7:C10 – conditional helper enables Average and Median for 2025, Service B, Bands 3 & 5.
B7: 5 | C7: Create a dynamic table or summary view that displays Availability % by month for 2025, which can be controlled using filters or slicers for both Band and Service. Accompany this with an appropriate visual to enable clear and interactive comparison across Bands and Services. | D7: Summary!A12:E25 + line chart – dynamic monthly view controlled by Service/Band dropdown filters.

Sheet Users
A1: Operational Area | B1: User | C1: FTE | D1: Band | E1: Start Date (US Format) | F1: Start Date (UK Format)
A2: Service A | B2: User1000 | C2: 1 | D2: Band 3 | E2: 12/1/2025 | F2: 45992
A3: Service A | B3: User1001 | C3: 1 | D3: Band 5 | E3: 9/22/2025 | F3: 45922
A4: Service B | B4: User1002 | C4: 0.8 | D4: Band 3 | E4: 10/6/2025 | F4: 45936
A5: Service C | B5: User1003 | C5: 1 | D5: Band 4 | E5: 12/1/2025 | F5: 45992
A6: Service A | B6: User1004 | C6: 1 | D6: Band 5 | E6: 9/15/2025 | F6: 45915
A7: Service B | B7: User1005 | C7: 1 | D7: Band 3 | E7: 10/6/2025 | F7: 45936
A8: Service B | B8: User1006 | C8: 1 | D8: Band 5 | E8: 11/3/2025 | F8: 45964
A9: Service B | B9: User1007 | C9: 1 | D9: Band 3 | E9: 10/6/2025 | F9: 45936
A10: Service A | B10: User1008 | C10: 1 | D10: Band 3 | E10: 12/1/2025 | F10: 45992
A11: Service B | B11: User1009 | C11: 1 | D11: Band 3 | E11: 10/1/2025 | F11: 45931
A12: Service A | B12: User1010 | C12: 0.9 | D12: Band 3 | E12: 12/2/2025 | F12: 45993
A13: Service A | B13: User1011 | C13: 0.81081081 | D13: Band 3 | E13: 9/15/2025 | F13: 45915
... A310: Service B | B310: User1308 | C310: 1 | D310: Band 5 | E310: 1/5/2026 | F310: 46027

Sheet Performance Data
A1: User | B1: Reporting Month | C1: Contracted Hours | D1: Available Hours | E1: Occupied Hours | F1: Availability % | G1: Service | H1: Band | I1: Service A & Band 3 | J1: Q4 Eligible Availability %
A2: User1000 | B2: 45992 | C2: 155.4 | D2: 0.5 | E2: 0.5 | F2: =IFERROR(IF(OR(C2="",D2="",C2=0),"",D2/C2),"") -> 0.0032175032 | G2: =IFERROR(INDEX(Users!$A$2:$A$310,MATCH(A2,Users!$B$2:$B$310,0)),"") -> Service A | H2: =IFERROR(INDEX(Users!$D$2:$D$310,MATCH(A2,Users!$B$2:$B$310,0)),"") -> Band 3 | I2: =AND(G2="Service A",H2="Band 3") -> TRUE | J2: =IF(AND(B2>=DATE(2025,1,1),B2<DATE(2026,1,1),G2="Service B",OR(H2="Band 3",H2="Band 5"),ISNUMBER(F2)),F2,"")
A3: User1000 | B3: 46023 | C3: 155.4 | F3: =IFERROR(IF(OR(C3="",D3="",C3=0),"",D3/C3),"") | G3: =IFERROR(INDEX(Users!$A$2:$A$310,MATCH(A3,Users!$B$2:$B$310,0)),"") -> Service A | H3: =IFERROR(INDEX(Users!$D$2:$D$310,MATCH(A3,Users!$B$2:$B$310,0)),"") -> Band 3 | I3: =AND(G3="Service A",H3="Band 3") -> TRUE | J3: =IF(AND(B3>=DATE(2025,1,1),B3<DATE(2026,1,1),G3="Service B",OR(H3="Band 3",H3="Band 5"),ISNUMBER(F3)),F3,"")
A4: User1001 | B4: 45901 | C4: 51.8 | D4: 14.8 | F4: =IFERROR(IF(OR(C4="",D4="",C4=0),"",D4/C4),"") -> 0.28571429 | G4: =IFERROR(INDEX(Users!$A$2:$A$310,MATCH(A4,Users!$B$2:$B$310,0)),"") -> Service A | H4: =IFERROR(INDEX(Users!$D$2:$D$310,MATCH(A4,Users!$B$2:$B$310,0)),"") -> Band 5 | I4: =AND(G4="Service A",H4="Band 3") -> FALSE | J4: =IF(AND(B4>=DATE(2025,1,1),B4<DATE(2026,1,1),G4="Service B",OR(H4="Band 3",H4="Band 5"),ISNUMBER(F4)),F4,"")
A5: User1001 | B5: 45931 | C5: 170.2 | D5: 170.7 | E5: 41 | F5: =IFERROR(IF(OR(C5="",D5="",C5=0),"",D5/C5),"") -> 1.0029377 | G5: =IFERROR(INDEX(Users!$A$2:$A$310,MATCH(A5,Users!$B$2:$B$310,0)),"") -> Service A | H5: =IFERROR(INDEX(Users!$D$2:$D$310,MATCH(A5,Users!$B$2:$B$310,0)),"") -> Band 5 | I5: =AND(G5="Service A",H5="Band 3") -> FALSE | J5: =IF(AND(B5>=DATE(2025,1,1),B5<DATE(2026,1,1),G5="Service B",OR(H5="Band 3",H5="Band 5"),ISNUMBER(F5)),F5,"")
A6: User1001 | B6: 45962 | C6: 148 | D6: 148.20333 | E6: 36.12 | F6: =IFERROR(IF(OR(C6="",D6="",C6=0),"",D6/C6),"") -> 1.0013739 | G6: =IFERROR(INDEX(Users!$A$2:$A$310,MATCH(A6,Users!$B$2:$B$310,0)),"") -> Service A | H6: =IFERROR(INDEX(Users!$D$2:$D$310,MATCH(A6,Users!$B$2:$B$310,0)),"") -> Band 5 | I6: =AND(G6="Service A",H6="Band 3") -> FALSE | J6: =IF(AND(B6>=DATE(2025,1,1),B6<DATE(2026,1,1),G6="Service B",OR(H6="Band 3",H6="Band 5"),ISNUMBER(F6)),F6,"")
A7: User1001 | B7: 45992 | C7: 155.4 | D7: 152.59667 | E7: 73.03 | F7: =IFERROR(IF(OR(C7="",D7="",C7=0),"",D7/C7),"") -> 0.98196053 | G7: =IFERROR(INDEX(Users!$A$2:$A$310,MATCH(A7,Users!$B$2:$B$310,0)),"") -> Service A | H7: =IFERROR(INDEX(Users!$D$2:$D$310,MATCH(A7,Users!$B$2:$B$310,0)),"") -> Band 5 | I7: =AND(G7="Service A",H7="Band 3") -> FALSE | J7: =IF(AND(B7>=DATE(2025,1,1),B7<DATE(2026,1,1),G7="Service B",OR(H7="Band 3",H7="Band 5"),ISNUMBER(F7)),F7,"")
A8: User1001 | B8: 46023 | C8: 155.4 | D8: 157.22 | E8: 72.32 | F8: =IFERROR(IF(OR(C8="",D8="",C8=0),"",D8/C8),"") -> 1.0117117 | G8: =IFERROR(INDEX(Users!$A$2:$A$310,MATCH(A8,Users!$B$2:$B$310,0)),"") -> Service A | H8: =IFERROR(INDEX(Users!$D$2:$D$310,MATCH(A8,Users!$B$2:$B$310,0)),"") -> Band 5 | I8: =AND(G8="Service A",H8="Band 3") -> FALSE | J8: =IF(AND(B8>=DATE(2025,1,1),B8<DATE(2026,1,1),G8="Service B",OR(H8="Band 3",H8="Band 5"),ISNUMBER(F8)),F8,"")
A9: User1002 | B9: 45931 | C9: 118.4 | D9: 126.95 | E9: 96.4 | F9: =IFERROR(IF(OR(C9="",D9="",C9=0),"",D9/C9),"") -> 1.0722128 | G9: =IFERROR(INDEX(Users!$A$2:$A$310,MATCH(A9,Users!$B$2:$B$310,0)),"") -> Service B | H9: =IFERROR(INDEX(Users!$D$2:$D$310,MATCH(A9,Users!$B$2:$B$310,0)),"") -> Band 3 | I9: =AND(G9="Service A",H9="Band 3") -> FALSE | J9: =IF(AND(B9>=DATE(2025,1,1),B9<DATE(2026,1,1),G9="Service B",OR(H9="Band 3",H9="Band 5"),ISNUMBER(F9)),F9,"") -> 1.0722128
A10: User1002 | B10: 45962 | C10: 118.4 | D10: 58.793333 | E10: 46.91 | F10: =IFERROR(IF(OR(C10="",D10="",C10=0),"",D10/C10),"") -> 0.49656532 | G10: =IFERROR(INDEX(Users!$A$2:$A$310,MATCH(A10,Users!$B$2:$B$310,0)),"") -> Service B | H10: =IFERROR(INDEX(Users!$D$2:$D$310,MATCH(A10,Users!$B$2:$B$310,0)),"") -> Band 3 | I10: =AND(G10="Service A",H10="Band 3") -> FALSE | J10: =IF(AND(B10>=DATE(2025,1,1),B10<DATE(2026,1,1),G10="Service B",OR(H10="Band 3",H10="Band 5"),ISNUMBER(F10)),F10,"") -> 0.49656532
A11: User1002 | B11: 45992 | C11: 118.4 | D11: 1.08 | E11: 1.08 | F11: =IFERROR(IF(OR(C11="",D11="",C11=0),"",D11/C11),"") -> 0.0091216216 | G11: =IFERROR(INDEX(Users!$A$2:$A$310,MATCH(A11,Users!$B$2:$B$310,0)),"") -> Service B | H11: =IFERROR(INDEX(Users!$D$2:$D$310,MATCH(A11,Users!$B$2:$B$310,0)),"") -> Band 3 | I11: =AND(G11="Service A",H11="Band 3") -> FALSE | J11: =IF(AND(B11>=DATE(2025,1,1),B11<DATE(2026,1,1),G11="Service B",OR(H11="Band 3",H11="Band 5"),ISNUMBER(F11)),F11,"") -> 0.0091216216
A12: User1002 | B12: 46023 | C12: 37 | D12: 13.033333 | E12: 4 | F12: =IFERROR(IF(OR(C12="",D12="",C12=0),"",D12/C12),"") -> 0.35225225 | G12: =IFERROR(INDEX(Users!$A$2:$A$310,MATCH(A12,Users!$B$2:$B$310,0)),"") -> Service B | H12: =IFERROR(INDEX(Users!$D$2:$D$310,MATCH(A12,Users!$B$2:$B$310,0)),"") -> Band 3 | I12: =AND(G12="Service A",H12="Band 3") -> FALSE | J12: =IF(AND(B12>=DATE(2025,1,1),B12<DATE(2026,1,1),G12="Service B",OR(H12="Band 3",H12="Band 5"),ISNUMBER(F12)),F12,"")
A13: User1003 | B13: 45992 | C13: 155.4 | D13: 75.016667 | E13: 0.25 | F13: =IFERROR(IF(OR(C13="",D13="",C13=0),"",D13/C13),"") -> 0.48273273 | G13: =IFERROR(INDEX(Users!$A$2:$A$310,MATCH(A13,Users!$B$2:$B$310,0)),"") -> Service C | H13: =IFERROR(INDEX(Users!$D$2:$D$310,MATCH(A13,Users!$B$2:$B$310,0)),"") -> Band 4 | I13: =AND(G13="Service A",H13="Band 3") -> FALSE | J13: =IF(AND(B13>=DATE(2025,1,1),B13<DATE(2026,1,1),G13="Service B",OR(H13="Band 3",H13="Band 5"),ISNUMBER(F13)),F13,"")
A14: User1003 | B14: 46023 | C14: 155.4 | D14: 152.05333 | E14: 15.32 | F14: =IFERROR(IF(OR(C14="",D14="",C14=0),"",D14/C14),"") -> 0.97846418 | G14: =IFERROR(INDEX(Users!$A$2:$A$310,MATCH(A14,Users!$B$2:$B$310,0)),"") -> Service C | H14: =IFERROR(INDEX(Users!$D$2:$D$310,MATCH(A14,Users!$B$2:$B$310,0)),"") -> Band 4 | I14: =AND(G14="Service A",H14="Band 3") -> FALSE | J14: =IF(AND(B14>=DATE(2025,1,1),B14<DATE(2026,1,1),G14="Service B",OR(H14="Band 3",H14="Band 5"),ISNUMBER(F14)),F14,"")
A15: User1004 | B15: 45901 | C15: 92.5 | D15: 75.38 | E15: 49.38 | F15: =IFERROR(IF(OR(C15="",D15="",C15=0),"",D15/C15),"") -> 0.81491892 | G15: =IFERROR(INDEX(Users!$A$2:$A$310,MATCH(A15,Users!$B$2:$B$310,0)),"") -> Service A | H15: =IFERROR(INDEX(Users!$D$2:$D$310,MATCH(A15,Users!$B$2:$B$310,0)),"") -> Band 5 | I15: =AND(G15="Service A",H15="Band 3") -> FALSE | J15: =IF(AND(B15>=DATE(2025,1,1),B15<DATE(2026,1,1),G15="Service B",OR(H15="Band 3",H15="Band 5"),ISNUMBER(F15)),F15,"")
A16: User1004 | B16: 45931 | C16: 166.5 | D16: 150.02 | E16: 90.27 | F16: =IFERROR(IF(OR(C16="",D16="",C16=0),"",D16/C16),"") -> 0.90102102 | G16: =IFERROR(INDEX(Users!$A$2:$A$310,MATCH(A16,Users!$B$2:$B$310,0)),"") -> Service A | H16: =IFERROR(INDEX(Users!$D$2:$D$310,MATCH(A16,Users!$B$2:$B$310,0)),"") -> Band 5 | I16: =AND(G16="Service A",H16="Band 3") -> FALSE | J16: =IF(AND(B16>=DATE(2025,1,1),B16<DATE(2026,1,1),G16="Service B",OR(H16="Band 3",H16="Band 5"),ISNUMBER(F16)),F16,"")
... A19: User1004 | B19: 46023 | C19: 148 | D19: 94.05 | E19: 59.5 | F19: =IFERROR(IF(OR(C19="",D19="",C19=0),"",D19/C19),"") -> 0.63547297 | G19: =IFERROR(INDEX(Users!$A$2:$A$310,MATCH(A19,Users!$B$2:$B$310,0)),"") -> Service A | H19: =IFERROR(INDEX(Users!$D$2:$D$310,MATCH(A19,Users!$B$2:$B$310,0)),"") -> Band 5 | I19: =AND(G19="Service A",H19="Band 3") -> FALSE | J19: =IF(AND(B19>=DATE(2025,1,1),B19<DATE(2026,1,1),G19="Service B",OR(H19="Band 3",H19="Band 5"),ISNUMBER(F19)),F19,"")
A20: User1005 | B20: 45931 | C20: 148 | D20: 117.76667 | F20: =IFERROR(IF(OR(C20="",D20="",C20=0),"",D20/C20),"") -> 0.79572072 | G20: =IFERROR(INDEX(Users!$A$2:$A$310,MATCH(A20,Users!$B$2:$B$310,0)),"") -> Service B | H20: =IFERROR(INDEX(Users!$D$2:$D$310,MATCH(A20,Users!$B$2:$B$310,0)),"") -> Band 3 | I20: =AND(G20="Service A",H20="Band 3") -> FALSE | J20: =IF(AND(B20>=DATE(2025,1,1),B20<DATE(2026,1,1),G20="Service B",OR(H20="Band 3",H20="Band 5"),ISNUMBER(F20)),F20,"") -> 0.79572072
A21: User1005 | B21: 45962 | C21: 148 | D21: 58.966667 | E21: 2.55 | F21: =IFERROR(IF(OR(C21="",D21="",C21=0),"",D21/C21),"") -> 0.39842342 | G21: =IFERROR(INDEX(Users!$A$2:$A$310,MATCH(A21,Users!$B$2:$B$310,0)),"") -> Service B | H21: =IFERROR(INDEX(Users!$D$2:$D$310,MATCH(A21,Users!$B$2:$B$310,0)),"") -> Band 3 | I21: =AND(G21="Service A",H21="Band 3") -> FALSE | J21: =IF(AND(B21>=DATE(2025,1,1),B21<DATE(2026,1,1),G21="Service B",OR(H21="Band 3",H21="Band 5"),ISNUMBER(F21)),F21,"") -> 0.39842342
A22: User1005 | B22: 45992 | C22: 155.4 | D22: 14 | E22: 14 | F22: =IFERROR(IF(OR(C22="",D22="",C22=0),"",D22/C22),"") -> 0.09009009 | G22: =IFERROR(INDEX(Users!$A$2:$A$310,MATCH(A22,Users!$B$2:$B$310,0)),"") -> Service B | H22: =IFERROR(INDEX(Users!$D$2:$D$310,MATCH(A22,Users!$B$2:$B$310,0)),"") -> Band 3 | I22: =AND(G22="Service A",H22="Band 3") -> FALSE | J22: =IF(AND(B22>=DATE(2025,1,1),B22<DATE(2026,1,1),G22="Service B",OR(H22="Band 3",H22="Band 5"),ISNUMBER(F22)),F22,"") -> 0.09009009
A23: User1005 | B23: 46023 | C23: 155.4 | D23: 150.58333 | E23: 34 | F23: =IFERROR(IF(OR(C23="",D23="",C23=0),"",D23/C23),"") -> 0.96900472 | G23: =IFERROR(INDEX(Users!$A$2:$A$310,MATCH(A23,Users!$B$2:$B$310,0)),"") -> Service B | H23: =IFERROR(INDEX(Users!$D$2:$D$310,MATCH(A23,Users!$B$2:$B$310,0)),"") -> Band 3 | I23: =AND(G23="Service A",H23="Band 3") -> FALSE | J23: =IF(AND(B23>=DATE(2025,1,1),B23<DATE(2026,1,1),G23="Service B",OR(H23="Band 3",H23="Band 5"),ISNUMBER(F23)),F23,"")
A24: User1006 | B24: 45962 | C24: 148 | F24: =IFERROR(IF(OR(C24="",D24="",C24=0),"",D24/C24),"") | G24: =IFERROR(INDEX(Users!$A$2:$A$310,MATCH(A24,Users!$B$2:$B$310,0)),"") -> Service B | H24: =IFERROR(INDEX(Users!$D$2:$D$310,MATCH(A24,Users!$B$2:$B$310,0)),"") -> Band 5 | I24: =AND(G24="Service A",H24="Band 3") -> FALSE | J24: =IF(AND(B24>=DATE(2025,1,1),B24<DATE(2026,1,1),G24="Service B",OR(H24="Band 3",H24="Band 5"),ISNUMBER(F24)),F24,"")
A25: User1006 | B25: 45992 | C25: 155.4 | F25: =IFERROR(IF(OR(C25="",D25="",C25=0),"",D25/C25),"") | G25: =IFERROR(INDEX(Users!$A$2:$A$310,MATCH(A25,Users!$B$2:$B$310,0)),"") -> Service B | H25: =IFERROR(INDEX(Users!$D$2:$D$310,MATCH(A25,Users!$B$2:$B$310,0)),"") -> Band 5 | I25: =AND(G25="Service A",H25="Band 3") -> FALSE | J25: =IF(AND(B25>=DATE(2025,1,1),B25<DATE(2026,1,1),G25="Service B",OR(H25="Band 3",H25="Band 5"),ISNUMBER(F25)),F25,"")
A26: User1006 | B26: 46023 | C26: 155.4 | F26: =IFERROR(IF(OR(C26="",D26="",C26=0),"",D26/C26),"") | G26: =IFERROR(INDEX(Users!$A$2:$A$310,MATCH(A26,Users!$B$2:$B$310,0)),"") -> Service B | H26: =IFERROR(INDEX(Users!$D$2:$D$310,MATCH(A26,Users!$B$2:$B$310,0)),"") -> Band 5 | I26: =AND(G26="Service A",H26="Band 3") -> FALSE | J26: =IF(AND(B26>=DATE(2025,1,1),B26<DATE(2026,1,1),G26="Service B",OR(H26="Band 3",H26="Band 5"),ISNUMBER(F26)),F26,"")
A27: User1007 | B27: 45931 | C27: 148 | D27: 52.033333 | F27: =IFERROR(IF(OR(C27="",D27="",C27=0),"",D27/C27),"") -> 0.35157658 | G27: =IFERROR(INDEX(Users!$A$2:$A$310,MATCH(A27,Users!$B$2:$B$310,0)),"") -> Service B | H27: =IFERROR(INDEX(Users!$D$2:$D$310,MATCH(A27,Users!$B$2:$B$310,0)),"") -> Band 3 | I27: =AND(G27="Service A",H27="Band 3") -> FALSE | J27: =IF(AND(B27>=DATE(2025,1,1),B27<DATE(2026,1,1),G27="Service B",OR(H27="Band 3",H27="Band 5"),ISNUMBER(F27)),F27,"") -> 0.35157658
A28: User1007 | B28: 45962 | C28: 148 | D28: 7.9166667 | F28: =IFERROR(IF(OR(C28="",D28="",C28=0),"",D28/C28),"") -> 0.053490991 | G28: =IFERROR(INDEX(Users!$A$2:$A$310,MATCH(A28,Users!$B$2:$B$310,0)),"") -> Service B | H28: =IFERROR(INDEX(Users!$D$2:$D$310,MATCH(A28,Users!$B$2:$B$310,0)),"") -> Band 3 | I28: =AND(G28="Service A",H28="Band 3") -> FALSE | J28: =IF(AND(B28>=DATE(2025,1,1),B28<DATE(2026,1,1),G28="Service B",OR(H28="Band 3",H28="Band 5"),ISNUMBER(F28)),F28,"") -> 0.053490991
A29: User1007 | B29: 45992 | C29: 155.4 | D29: 1.25 | E29: 1.25 | F29: =IFERROR(IF(OR(C29="",D29="",C29=0),"",D29/C29),"") -> 0.008043758 | G29: =IFERROR(INDEX(Users!$A$2:$A$310,MATCH(A29,Users!$B$2:$B$310,0)),"") -> Service B | H29: =IFERROR(INDEX(Users!$D$2:$D$310,MATCH(A29,Users!$B$2:$B$310,0)),"") -> Band 3 | I29: =AND(G29="Service A",H29="Band 3") -> FALSE | J29: =IF(AND(B29>=DATE(2025,1,1),B29<DATE(2026,1,1),G29="Service B",OR(H29="Band 3",H29="Band 5"),ISNUMBER(F29)),F29,"") -> 0.008043758
A30: User1007 | B30: 46023 | C30: 155.4 | D30: 95.06 | E30: 22.31 | F30: =IFERROR(IF(OR(C30="",D30="",C30=0),"",D30/C30),"") -> 0.61171171 | G30: =IFERROR(INDEX(Users!$A$2:$A$310,MATCH(A30,Users!$B$2:$B$310,0)),"") -> Service B | H30: =IFERROR(INDEX(Users!$D$2:$D$310,MATCH(A30,Users!$B$2:$B$310,0)),"") -> Band 3 | I30: =AND(G30="Service A",H30="Band 3") -> FALSE | J30: =IF(AND(B30>=DATE(2025,1,1),B30<DATE(2026,1,1),G30="Service B",OR(H30="Band 3",H30="Band 5"),ISNUMBER(F30)),F30,"")
A31: User1008 | B31: 45992 | C31: 155.4 | D31: 81.4 | F31: =IFERROR(IF(OR(C31="",D31="",C31=0),"",D31/C31),"") -> 0.52380952 | G31: =IFERROR(INDEX(Users!$A$2:$A$310,MATCH(A31,Users!$B$2:$B$310,0)),"") -> Service A | H31: =IFERROR(INDEX(Users!$D$2:$D$310,MATCH(A31,Users!$B$2:$B$310,0)),"") -> Band 3 | I31: =AND(G31="Service A",H31="Band 3") -> TRUE | J31: =IF(AND(B31>=DATE(2025,1,1),B31<DATE(2026,1,1),G31="Service B",OR(H31="Band 3",H31="Band 5"),ISNUMBER(F31)),F31,"")
A32: User1008 | B32: 46023 | C32: 155.4 | D32: 140.6 | F32: =IFERROR(IF(OR(C32="",D32="",C32=0),"",D32/C32),"") -> 0.9047619 | G32: =IFERROR(INDEX(Users!$A$2:$A$310,MATCH(A32,Users!$B$2:$B$310,0)),"") -> Service A | H32: =IFERROR(INDEX(Users!$D$2:$D$310,MATCH(A32,Users!$B$2:$B$310,0)),"") -> Band 3 | I32: =AND(G32="Service A",H32="Band 3") -> TRUE | J32: =IF(AND(B32>=DATE(2025,1,1),B32<DATE(2026,1,1),G32="Service B",OR(H32="Band 3",H32="Band 5"),ISNUMBER(F32)),F32,"")
A33: User1009 | B33: 45901 | F33: =IFERROR(IF(OR(C33="",D33="",C33=0),"",D33/C33),"") | G33: =IFERROR(INDEX(Users!$A$2:$A$310,MATCH(A33,Users!$B$2:$B$310,0)),"") -> Service B | H33: =IFERROR(INDEX(Users!$D$2:$D$310,MATCH(A33,Users!$B$2:$B$310,0)),"") -> Band 3 | I33: =AND(G33="Service A",H33="Band 3") -> FALSE | J33: =IF(AND(B33>=DATE(2025,1,1),B33<DATE(2026,1,1),G33="Service B",OR(H33="Band 3",H33="Band 5"),ISNUMBER(F33)),F33,"")
A34: User1009 | B34: 45931 | C34: 166.5 | F34: =IFERROR(IF(OR(C34="",D34="",C34=0),"",D34/C34),"") | G34: =IFERROR(INDEX(Users!$A$2:$A$310,MATCH(A34,Users!$B$2:$B$310,0)),"") -> Service B | H34: =IFERROR(INDEX(Users!$D$2:$D$310,MATCH(A34,Users!$B$2:$B$310,0)),"") -> Band 3 | I34: =AND(G34="Service A",H34="Band 3") -> FALSE | J34: =IF(AND(B34>=DATE(2025,1,1),B34<DATE(2026,1,1),G34="Service B",OR(H34="Band 3",H34="Band 5"),ISNUMBER(F34)),F34,"")
A35: User1009 | B35: 45962 | C35: 148 | D35: 56.781111 | F35: =IFERROR(IF(OR(C35="",D35="",C35=0),"",D35/C35),"") -> 0.38365616 | G35: =IFERROR(INDEX(Users!$A$2:$A$310,MATCH(A35,Users!$B$2:$B$310,0)),"") -> Service B | H35: =IFERROR(INDEX(Users!$D$2:$D$310,MATCH(A35,Users!$B$2:$B$310,0)),"") -> Band 3 | I35: =AND(G35="Service A",H35="Band 3") -> FALSE | J35: =IF(AND(B35>=DATE(2025,1,1),B35<DATE(2026,1,1),G35="Service B",OR(H35="Band 3",H35="Band 5"),ISNUMBER(F35)),F35,"") -> 0.38365616
A36: User1009 | B36: 45992 | C36: 166.5 | D36: 1.42 | E36: 1.42 | F36: =IFERROR(IF(OR(C36="",D36="",C36=0),"",D36/C36),"") -> 0.0085285285 | G36: =IFERROR(INDEX(Users!$A$2:$A$310,MATCH(A36,Users!$B$2:$B$310,0)),"") -> Service B | H36: =IFERROR(INDEX(Users!$D$2:$D$310,MATCH(A36,Users!$B$2:$B$310,0)),"") -> Band 3 | I36: =AND(G36="Service A",H36="Band 3") -> FALSE | J36: =IF(AND(B36>=DATE(2025,1,1),B36<DATE(2026,1,1),G36="Service B",OR(H36="Band 3",H36="Band 5"),ISNUMBER(F36)),F36,"") -> 0.0085285285
A37: User1009 | B37: 46023 | C37: 148 | D37: 2.53 | E37: 2.53 | F37: =IFERROR(IF(OR(C37="",D37="",C37=0),"",D37/C37),"") -> 0.017094595 | G37: =IFERROR(INDEX(Users!$A$2:$A$310,MATCH(A37,Users!$B$2:$B$310,0)),"") -> Service B | H37: =IFERROR(INDEX(Users!$D$2:$D$310,MATCH(A37,Users!$B$2:$B$310,0)),"") -> Band 3 | I37: =AND(G37="Service A",H37="Band 3") -> FALSE | J37: =IF(AND(B37>=DATE(2025,1,1),B37<DATE(2026,1,1),G37="Service B",OR(H37="Band 3",H37="Band 5"),ISNUMBER(F37)),F37,"")
A38: User1010 | B38: 45992 | C38: 133.2 | F38: =IFERROR(IF(OR(C38="",D38="",C38=0),"",D38/C38),"") | G38: =IFERROR(INDEX(Users!$A$2:$A$310,MATCH(A38,Users!$B$2:$B$310,0)),"") -> Service A | H38: =IFERROR(INDEX(Users!$D$2:$D$310,MATCH(A38,Users!$B$2:$B$310,0)),"") -> Band 3 | I38: =AND(G38="Service A",H38="Band 3") -> TRUE | J38: =IF(AND(B38>=DATE(2025,1,1),B38<DATE(2026,1,1),G38="Service B",OR(H38="Band 3",H38="Band 5"),ISNUMBER(F38)),F38,"")
A39: User1010 | B39: 46023 | C39: 140.6 | F39: =IFERROR(IF(OR(C39="",D39="",C39=0),"",D39/C39),"") | G39: =IFERROR(INDEX(Users!$A$2:$A$310,MATCH(A39,Users!$B$2:$B$310,0)),"") -> Service A | H39: =IFERROR(INDEX(Users!$D$2:$D$310,MATCH(A39,Users!$B$2:$B$310,0)),"") -> Band 3 | I39: =AND(G39="Service A",H39="Band 3") -> TRUE | J39: =IF(AND(B39>=DATE(2025,1,1),B39<DATE(2026,1,1),G39="Service B",OR(H39="Band 3",H39="Band 5"),ISNUMBER(F39)),F39,"")
A40: User1011 | B40: 45901 | C40: 76 | D40: 72.903333 | E40: 57.07 | F40: =IFERROR(IF(OR(C40="",D40="",C40=0),"",D40/C40),"") -> 0.95925439 | G40: =IFERROR(INDEX(Users!$A$2:$A$310,MATCH(A40,Users!$B$2:$B$310,0)),"") -> Service A | H40: =IFERROR(INDEX(Users!$D$2:$D$310,MATCH(A40,Users!$B$2:$B$310,0)),"") -> Band 3 | I40: =AND(G40="Service A",H40="Band 3") -> TRUE | J40: =IF(AND(B40>=DATE(2025,1,1),B40<DATE(2026,1,1),G40="Service B",OR(H40="Band 3",H40="Band 5"),ISNUMBER(F40)),F40,"")
A41: User1011 | B41: 45931 | C41: 134 | D41: 119.17667 | E41: 87.01 | F41: =IFERROR(IF(OR(C41="",D41="",C41=0),"",D41/C41),"") -> 0.88937811 | G41: =IFERROR(INDEX(Users!$A$2:$A$310,MATCH(A41,Users!$B$2:$B$310,0)),"") -> Service A | H41: =IFERROR(INDEX(Users!$D$2:$D$310,MATCH(A41,Users!$B$2:$B$310,0)),"") -> Band 3 | I41: =AND(G41="Service A",H41="Band 3") -> TRUE | J41: =IF(AND(B41>=DATE(2025,1,1),B41<DATE(2026,1,1),G41="Service B",OR(H41="Band 3",H41="Band 5"),ISNUMBER(F41)),F41,"")
A42: User1011 | B42: 45962 | C42: 120 | D42: 107.5 | E42: 87.5 | F42: =IFERROR(IF(OR(C42="",D42="",C42=0),"",D42/C42),"") -> 0.89583333 | G42: =IFERROR(INDEX(Users!$A$2:$A$310,MATCH(A42,Users!$B$2:$B$310,0)),"") -> Service A | H42: =IFERROR(INDEX(Users!$D$2:$D$310,MATCH(A42,Users!$B$2:$B$310,0)),"") -> Band 3 | I42: =AND(G42="Service A",H42="Band 3") -> TRUE | J42: =IF(AND(B42>=DATE(2025,1,1),B42<DATE(2026,1,1),G42="Service B",OR(H42="Band 3",H42="Band 5"),ISNUMBER(F42)),F42,"")
...

Sheet Summary
A1: Data Analyst Practical Test – Solution Summary
A3: Service filter | B3: Service B | D3: How to use | E3: Change the yellow dropdowns to filter the 2025 monthly view.
A4: Band filter | B4: Band 3 | D4: Comparison | E4: Chart compares the selected combination with Service, Band and Overall averages.
A7: Question 4 – 2025 Service B, Band 3 & Band 5
A8: Metric | B8: Result | C8: QA check
A9: Average Availability % | B9: =IFERROR(AVERAGE('Performance Data'!$J$2:$J$2540),"") -> 0.78907875 | C9: 0.78907875
A10: Median Availability % | B10: =IFERROR(MEDIAN('Performance Data'!$J$2:$J$2540),"") -> 0.85051312 | C10: 0.85051312
A12: Question 5 – Dynamic 2025 Monthly Availability View
A13: Month | B13: Selected Service + Band | C13: Selected Service (all Bands) | D13: Selected Band (all Services) | E13: Overall
A14: 45658 | B14: =IFERROR(IF(AND($B$3="All",$B$4="All"),SUMIFS('Performance Data'!$F$2:$F$2540,'Performance Data'!$B$2:$B$2540,A14)/COUNTIFS('Performance Data'!$B$2:$B$2540,A14,'Performance Data'!$F$2:$F$2540,">=0"),IF($B$3="All",SUMIFS('Performance Data'!$F$2:$F$2540,'Performance Data'!$B$2:$B$2540,A14,'Performance Data'!$H$2:$H$2540,$B$4)/COUNTIFS('Performance Data'!$B$2:$B$2540,A14,'Performance Data'!$H$2:$H$2540,$B$4,'Performance Data'!$F$2:$F$2540,">=0"),IF($B$4="All",SUMIFS('Performance Data'!$F$2:$F$2540,'Performance Data'!$B$2:$B$2540,A14,'Performance Data'!$G$2:$G$2540,$B$3)/COUNTIFS('Performance Data'!$B$2:$B$2540,A14,'Performance Data'!$G$2:$G$2540,$B$3,'Performance Data'!$F$2:$F$2540,">=0"),SUMIFS('Performance Data'!$F$2:$F$2540,'Performance Data'!$B$2:$B$2540,A14,'Performance Data'!$G$2:$G$2540,$B$3,'Performance Data'!$H$2:$H$2540,$B$4)/COUNTIFS('Performance Data'!$B$2:$B$2540,A14,'Performance Data'!$G$2:$G$2540,$B$3,'Performance Data'!$H$2:$H$2540,$B$4,'Performance Data'!$F$2:$F$2540,">=0")))),"") -> 0.75928772 | C14: =IFERROR(IF($B$3="All",SUMIFS('Performance Data'!$F$2:$F$2540,'Performance Data'!$B$2:$B$2540,A14)/COUNTIFS('Performance Data'!$B$2:$B$2540,A14,'Performance Data'!$F$2:$F$2540,">=0"),SUMIFS('Performance Data'!$F$2:$F$2540,'Performance Data'!$B$2:$B$2540,A14,'Performance Data'!$G$2:$G$2540,$B$3)/COUNTIFS('Performance Data'!$B$2:$B$2540,A14,'Performance Data'!$G$2:$G$2540,$B$3,'Performance Data'!$F$2:$F$2540,">=0")),"") -> 0.77309566 | D14: =IFERROR(IF($B$4="All",SUMIFS('Performance Data'!$F$2:$F$2540,'Performance Data'!$B$2:$B$2540,A14)/COUNTIFS('Performance Data'!$B$2:$B$2540,A14,'Performance Data'!$F$2:$F$2540,">=0"),SUMIFS('Performance Data'!$F$2:$F$2540,'Performance Data'!$B$2:$B$2540,A14,'Performance Data'!$H$2:$H$2540,$B$4)/COUNTIFS('Performance Data'!$B$2:$B$2540,A14,'Performance Data'!$H$2:$H$2540,$B$4,'Performance Data'!$F$2:$F$2540,">=0")),"") -> 0.81852116 | E14: =IFERROR(SUMIFS('Performance Data'!$F$2:$F$2540,'Performance Data'!$B$2:$B$2540,A14)/COUNTIFS('Performance Data'!$B$2:$B$2540,A14,'Performance Data'!$F$2:$F$2540,">=0"),"") -> 0.82911243
A15: 45689 | B15: =IFERROR(IF(AND($B$3="All",$B$4="All"),SUMIFS('Performance Data'!$F$2:$F$2540,'Performance Data'!$B$2:$B$2540,A15)/COUNTIFS('Performance Data'!$B$2:$B$2540,A15,'Performance Data'!$F$2:$F$2540,">=0"),IF($B$3="All",SUMIFS('Performance Data'!$F$2:$F$2540,'Performance Data'!$B$2:$B$2540,A15,'Performance Data'!$H$2:$H$2540,$B$4)/COUNTIFS('Performance Data'!$B$2:$B$2540,A15,'Performance Data'!$H$2:$H$2540,$B$4,'Performance Data'!$F$2:$F$2540,">=0"),IF($B$4="All",SUMIFS('Performance Data'!$F$2:$F$2540,'Performance Data'!$B$2:$B$2540,A15,'Performance Data'!$G$2:$G$2540,$B$3)/COUNTIFS('Performance Data'!$B$2:$B$2540,A15,'Performance Data'!$G$2:$G$2540,$B$3,'Performance Data'!$F$2:$F$2540,">=0"),SUMIFS('Performance Data'!$F$2:$F$2540,'Performance Data'!$B$2:$B$2540,A15,'Performance Data'!$G$2:$G$2540,$B$3,'Performance Data'!$H$2:$H$2540,$B$4)/COUNTIFS('Performance Data'!$B$2:$B$2540,A15,'Performance Data'!$G$2:$G$2540,$B$3,'Performance Data'!$H$2:$H$2540,$B$4,'Performance Data'!$F$2:$F$2540,">=0")))),"") -> 0.84255615 | C15: =IFERROR(IF($B$3="All",SUMIFS('Performance Data'!$F$2:$F$2540,'Performance Data'!$B$2:$B$2540,A15)/COUNTIFS('Performance Data'!$B$2:$B$2540,A15,'Performance Data'!$F$2:$F$2540,">=0"),SUMIFS('Performance Data'!$F$2:$F$2540,'Performance Data'!$B$2:$B$2540,A15,'Performance Data'!$G$2:$G$2540,$B$3)/COUNTIFS('Performance Data'!$B$2:$B$2540,A15,'Performance Data'!$G$2:$G$2540,$B$3,'Performance Data'!$F$2:$F$2540,">=0")),"") -> 0.84701193 | D15: =IFERROR(IF($B$4="All",SUMIFS('Performance Data'!$F$2:$F$2540,'Performance Data'!$B$2:$B$2540,A15)/COUNTIFS('Performance Data'!$B$2:$B$2540,A15,'Performance Data'!$F$2:$F$2540,">=0"),SUMIFS('Performance Data'!$F$2:$F$2540,'Performance Data'!$B$2:$B$2540,A15,'Performance Data'!$H$2:$H$2540,$B$4)/COUNTIFS('Performance Data'!$B$2:$B$2540,A15,'Performance Data'!$H$2:$H$2540,$B$4,'Performance Data'!$F$2:$F$2540,">=0")),"") -> 0.84907992 | E15: =IFERROR(SUMIFS('Performance Data'!$F$2:$F$2540,'Performance Data'!$B$2:$B$2540,A15)/COUNTIFS('Performance Data'!$B$2:$B$2540,A15,'Performance Data'!$F$2:$F$2540,">=0"),"") -> 0.86268725
A16: 45717 | B16: =IFERROR(IF(AND($B$3="All",$B$4="All"),SUMIFS('Performance Data'!$F$2:$F$2540,'Performance Data'!$B$2:$B$2540,A16)/COUNTIFS('Performance Data'!$B$2:$B$2540,A16,'Performance Data'!$F$2:$F$2540,">=0"),IF($B$3="All",SUMIFS('Performance Data'!$F$2:$F$2540,'Performance Data'!$B$2:$B$2540,A16,'Performance Data'!$H$2:$H$2540,$B$4)/COUNTIFS('Performance Data'!$B$2:$B$2540,A16,'Performance Data'!$H$2:$H$2540,$B$4,'Performance Data'!$F$2:$F$2540,">=0"),IF($B$4="All",SUMIFS('Performance Data'!$F$2:$F$2540,'Performance Data'!$B$2:$B$2540,A16,'Performance Data'!$G$2:$G$2540,$B$3)/COUNTIFS('Performance Data'!$B$2:$B$2540,A16,'Performance Data'!$G$2:$G$2540,$B$3,'Performance Data'!$F$2:$F$2540,">=0"),SUMIFS('Performance Data'!$F$2:$F$2540,'Performance Data'!$B$2:$B$2540,A16,'Performance Data'!$G$2:$G$2540,$B$3,'Performance Data'!$H$2:$H$2540,$B$4)/COUNTIFS('Performance Data'!$B$2:$B$2540,A16,'Performance Data'!$G$2:$G$2540,$B$3,'Performance Data'!$H$2:$H$2540,$B$4,'Performance Data'!$F$2:$F$2540,">=0")))),"") -> 0.82654335 | C16: =IFERROR(IF($B$3="All",SUMIFS('Performance Data'!$F$2:$F$2540,'Performance Data'!$B$2:$B$2540,A16)/COUNTIFS('Performance Data'!$B$2:$B$2540,A16,'Performance Data'!$F$2:$F$2540,">=0"),SUMIFS('Performance Data'!$F$2:$F$2540,'Performance Data'!$B$2:$B$2540,A16,'Performance Data'!$G$2:$G$2540,$B$3)/COUNTIFS('Performance Data'!$B$2:$B$2540,A16,'Performance Data'!$G$2:$G$2540,$B$3,'Performance Data'!$F$2:$F$2540,">=0")),"") -> 0.83431386 | D16: =IFERROR(IF($B$4="All",SUMIFS('Performance Data'!$F$2:$F$2540,'Performance Data'!$B$2:$B$2540,A16)/COUNTIFS('Performance Data'!$B$2:$B$2540,A16,'Performance Data'!$F$2:$F$2540,">=0"),SUMIFS('Performance Data'!$F$2:$F$2540,'Performance Data'!$B$2:$B$2540,A16,'Performance Data'!$H$2:$H$2540,$B$4)/COUNTIFS('Performance Data'!$B$2:$B$2540,A16,'Performance Data'!$H$2:$H$2540,$B$4,'Performance Data'!$F$2:$F$2540,">=0")),"") -> 0.8624526 | E16: =IFERROR(SUMIFS('Performance Data'!$F$2:$F$2540,'Performance Data'!$B$2:$B$2540,A16)/COUNTIFS('Performance Data'!$B$2:$B$2540,A16,'Performance Data'!$F$2:$F$2540,">=0"),"") -> 0.87112123
A17: 45748 | B17: =IFERROR(IF(AND($B$3="All",$B$4="All"),SUMIFS('Performance Data'!$F$2:$F$2540,'Performance Data'!$B$2:$B$2540,A17)/COUNTIFS('Performance Data'!$B$2:$B$2540,A17,'Performance Data'!$F$2:$F$2540,">=0"),IF($B$3="All",SUMIFS('Performance Data'!$F$2:$F$2540,'Performance Data'!$B$2:$B$2540,A17,'Performance Data'!$H$2:$H$2540,$B$4)/COUNTIFS('Performance Data'!$B$2:$B$2540,A17,'Performance Data'!$H$2:$H$2540,$B$4,'Performance Data'!$F$2:$F$2540,">=0"),IF($B$4="All",SUMIFS('Performance Data'!$F$2:$F$2540,'Performance Data'!$B$2:$B$2540,A17,'Performance Data'!$G$2:$G$2540,$B$3)/COUNTIFS('Performance Data'!$B$2:$B$2540,A17,'Performance Data'!$G$2:$G$2540,$B$3,'Performance Data'!$F$2:$F$2540,">=0"),SUMIFS('Performance Data'!$F$2:$F$2540,'Performance Data'!$B$2:$B$2540,A17,'Performance Data'!$G$2:$G$2540,$B$3,'Performance Data'!$H$2:$H$2540,$B$4)/COUNTIFS('Performance Data'!$B$2:$B$2540,A17,'Performance Data'!$G$2:$G$2540,$B$3,'Performance Data'!$H$2:$H$2540,$B$4,'Performance Data'!$F$2:$F$2540,">=0")))),"") -> 0.7680935 | C17: =IFERROR(IF($B$3="All",SUMIFS('Performance Data'!$F$2:$F$2540,'Performance Data'!$B$2:$B$2540,A17)/COUNTIFS('Performance Data'!$B$2:$B$2540,A17,'Performance Data'!$F$2:$F$2540,">=0"),SUMIFS('Performance Data'!$F$2:$F$2540,'Performance Data'!$B$2:$B$2540,A17,'Performance Data'!$G$2:$G$2540,$B$3)/COUNTIFS('Performance Data'!$B$2:$B$2540,A17,'Performance Data'!$G$2:$G$2540,$B$3,'Performance Data'!$F$2:$F$2540,">=0")),"") -> 0.77075159 | D17: =IFERROR(IF($B$4="All",SUMIFS('Performance Data'!$F$2:$F$2540,'Performance Data'!$B$2:$B$2540,A17)/COUNTIFS('Performance Data'!$B$2:$B$2540,A17,'Performance Data'!$F$2:$F$2540,">=0"),SUMIFS('Performance Data'!$F$2:$F$2540,'Performance Data'!$B$2:$B$2540,A17,'Performance Data'!$H$2:$H$2540,$B$4)/COUNTIFS('Performance Data'!$B$2:$B$2540,A17,'Performance Data'!$H$2:$H$2540,$B$4,'Performance Data'!$F$2:$F$2540,">=0")),"") -> 0.78487536 | E17: =IFERROR(SUMIFS('Performance Data'!$F$2:$F$2540,'Performance Data'!$B$2:$B$2540,A17)/COUNTIFS('Performance Data'!$B$2:$B$2540,A17,'Performance Data'!$F$2:$F$2540,">=0"),"") -> 0.79714363
A18: 45778 | B18: =IFERROR(IF(AND($B$3="All",$B$4="All"),SUMIFS('Performance Data'!$F$2:$F$2540,'Performance Data'!$B$2:$B$2540,A18)/COUNTIFS('Performance Data'!$B$2:$B$2540,A18,'Performance Data'!$F$2:$F$2540,">=0"),IF($B$3="All",SUMIFS('Performance Data'!$F$2:$F$2540,'Performance Data'!$B$2:$B$2540,A18,'Performance Data'!$H$2:$H$2540,$B$4)/COUNTIFS('Performance Data'!$B$2:$B$2540,A18,'Performance Data'!$H$2:$H$2540,$B$4,'Performance Data'!$F$2:$F$2540,">=0"),IF($B$4="All",SUMIFS('Performance Data'!$F$2:$F$2540,'Performance Data'!$B$2:$B$2540,A18,'Performance Data'!$G$2:$G$2540,$B$3)/COUNTIFS('Performance Data'!$B$2:$B$2540,A18,'Performance Data'!$G$2:$G$2540,$B$3,'Performance Data'!$F$2:$F$2540,">=0"),SUMIFS('Performance Data'!$F$2:$F$2540,'Performance Data'!$B$2:$B$2540,A18,'Performance Data'!$G$2:$G$2540,$B$3,'Performance Data'!$H$2:$H$2540,$B$4)/COUNTIFS('Performance Data'!$B$2:$B$2540,A18,'Performance Data'!$G$2:$G$2540,$B$3,'Performance Data'!$H$2:$H$2540,$B$4,'Performance Data'!$F$2:$F$2540,">=0")))),"") -> 0.79266896 | C18: =IFERROR(IF($B$3="All",SUMIFS('Performance Data'!$F$2:$F$2540,'Performance Data'!$B$2:$B$2540,A18)/COUNTIFS('Performance Data'!$B$2:$B$2540,A18,'Performance Data'!$F$2:$F$2540,">=0"),SUMIFS('Performance Data'!$F$2:$F$2540,'Performance Data'!$B$2:$B$2540,A18,'Performance Data'!$G$2:$G$2540,$B$3)/COUNTIFS('Performance Data'!$B$2:$B$2540,A18,'Performance Data'!$G$2:$G$2540,$B$3,'Performance Data'!$F$2:$F$2540,">=0")),"") -> 0.79120837 | D18: =IFERROR(IF($B$4="All",SUMIFS('Performance Data'!$F$2:$F$2540,'Performance Data'!$B$2:$B$2540,A18)/COUNTIFS('Performance Data'!$B$2:$B$2540,A18,'Performance Data'!$F$2:$F$2540,">=0"),SUMIFS('Performance Data'!$F$2:$F$2540,'Performance Data'!$B$2:$B$2540,A18,'Performance Data'!$H$2:$H$2540,$B$4)/COUNTIFS('Performance Data'!$B$2:$B$2540,A18,'Performance Data'!$H$2:$H$2540,$B$4,'Performance Data'!$F$2:$F$2540,">=0")),"") -> 0.79929211 | E18: =IFERROR(SUMIFS('Performance Data'!$F$2:$F$2540,'Performance Data'!$B$2:$B$2540,A18)/COUNTIFS('Performance Data'!$B$2:$B$2540,A18,'Performance Data'!$F$2:$F$2540,">=0"),"") -> 0.8032897
A19: 45809 | B19: =IFERROR(IF(AND($B$3="All",$B$4="All"),SUMIFS('Performance Data'!$F$2:$F$2540,'Performance Data'!$B$2:$B$2540,A19)/COUNTIFS('Performance Data'!$B$2:$B$2540,A19,'Performance Data'!$F$2:$F$2540,">=0"),IF($B$3="All",SUMIFS('Performance Data'!$F$2:$F$2540,'Performance Data'!$B$2:$B$2540,A19,'Performance Data'!$H$2:$H$2540,$B$4)/COUNTIFS('Performance Data'!$B$2:$B$2540,A19,'Performance Data'!$H$2:$H$2540,$B$4,'Performance Data'!$F$2:$F$2540,">=0"),IF($B$4="All",SUMIFS('Performance Data'!$F$2:$F$2540,'Performance Data'!$B$2:$B$2540,A19,'Performance Data'!$G$2:$G$2540,$B$3)/COUNTIFS('Performance Data'!$B$2:$B$2540,A19,'Performance Data'!$G$2:$G$2540,$B$3,'Performance Data'!$F$2:$F$2540,">=0"),SUMIFS('Performance Data'!$F$2:$F$2540,'Performance Data'!$B$2:$B$2540,A19,'Performance Data'!$G$2:$G$2540,$B$3,'Performance Data'!$H$2:$H$2540,$B$4)/COUNTIFS('Performance Data'!$B$2:$B$2540,A19,'Performance Data'!$G$2:$G$2540,$B$3,'Performance Data'!$H$2:$H$2540,$B$4,'Performance Data'!$F$2:$F$2540,">=0")))),"") -> 0.80812651 | C19: =IFERROR(IF($B$3="All",SUMIFS('Performance Data'!$F$2:$F$2540,'Performance Data'!$B$2:$B$2540,A19)/COUNTIFS('Performance Data'!$B$2:$B$2540,A19,'Performance Data'!$F$2:$F$2540,">=0"),SUMIFS('Performance Data'!$F$2:$F$2540,'Performance Data'!$B$2:$B$2540,A19,'Performance Data'!$G$2:$G$2540,$B$3)/COUNTIFS('Performance Data'!$B$2:$B$2540,A19,'Performance Data'!$G$2:$G$2540,$B$3,'Performance Data'!$F$2:$F$2540,">=0")),"") -> 0.81422627 | D19: =IFERROR(IF($B$4="All",SUMIFS('Performance Data'!$F$2:$F$2540,'Performance Data'!$B$2:$B$2540,A19)/COUNTIFS('Performance Data'!$B$2:$B$2540,A19,'Performance Data'!$F$2:$F$2540,">=0"),SUMIFS('Performance Data'!$F$2:$F$2540,'Performance Data'!$B$2:$B$2540,A19,'Performance Data'!$H$2:$H$2540,$B$4)/COUNTIFS('Performance Data'!$B$2:$B$2540,A19,'Performance Data'!$H$2:$H$2540,$B$4,'Performance Data'!$F$2:$F$2540,">=0")),"") -> 0.82929173 | E19: =IFERROR(SUMIFS('Performance Data'!$F$2:$F$2540,'Performance Data'!$B$2:$B$2540,A19)/COUNTIFS('Performance Data'!$B$2:$B$2540,A19,'Performance Data'!$F$2:$F$2540,">=0"),"") -> 0.83772507
A20: 45839 | B20: =IFERROR(IF(AND($B$3="All",$B$4="All"),SUMIFS('Performance Data'!$F$2:$F$2540,'Performance Data'!$B$2:$B$2540,A20)/COUNTIFS('Performance Data'!$B$2:$B$2540,A20,'Performance Data'!$F$2:$F$2540,">=0"),IF($B$3="All",SUMIFS('Performance Data'!$F$2:$F$2540,'Performance Data'!$B$2:$B$2540,A20,'Performance Data'!$H$2:$H$2540,$B$4)/COUNTIFS('Performance Data'!$B$2:$B$2540,A20,'Performance Data'!$H$2:$H$2540,$B$4,'Performance Data'!$F$2:$F$2540,">=0"),IF($B$4="All",SUMIFS('Performance Data'!$F$2:$F$2540,'Performance Data'!$B$2:$B$2540,A20,'Performance Data'!$G$2:$G$2540,$B$3)/COUNTIFS('Performance Data'!$B$2:$B$2540,A20,'Performance Data'!$G$2:$G$2540,$B$3,'Performance Data'!$F$2:$F$2540,">=0"),SUMIFS('Performance Data'!$F$2:$F$2540,'Performance Data'!$B$2:$B$2540,A20,'Performance Data'!$G$2:$G$2540,$B$3,'Performance Data'!$H$2:$H$2540,$B$4)/COUNTIFS('Performance Data'!$B$2:$B$2540,A20,'Performance Data'!$G$2:$G$2540,$B$3,'Performance Data'!$H$2:$H$2540,$B$4,'Performance Data'!$F$2:$F$2540,">=0")))),"") -> 0.82427948 | C20: =IFERROR(IF($B$3="All",SUMIFS('Performance Data'!$F$2:$F$2540,'Performance Data'!$B$2:$B$2540,A20)/COUNTIFS('Performance Data'!$B$2:$B$2540,A20,'Performance Data'!$F$2:$F$2540,">=0"),SUMIFS('Performance Data'!$F$2:$F$2540,'Performance Data'!$B$2:$B$2540,A20,'Performance Data'!$G$2:$G$2540,$B$3)/COUNTIFS('Performance Data'!$B$2:$B$2540,A20,'Performance Data'!$G$2:$G$2540,$B$3,'Performance Data'!$F$2:$F$2540,">=0")),"") -> 0.83296931 | D20: =IFERROR(IF($B$4="All",SUMIFS('Performance Data'!$F$2:$F$2540,'Performance Data'!$B$2:$B$2540,A20)/COUNTIFS('Performance Data'!$B$2:$B$2540,A20,'Performance Data'!$F$2:$F$2540,">=0"),SUMIFS('Performance Data'!$F$2:$F$2540,'Performance Data'!$B$2:$B$2540,A20,'Performance Data'!$H$2:$H$2540,$B$4)/COUNTIFS('Performance Data'!$B$2:$B$2540,A20,'Performance Data'!$H$2:$H$2540,$B$4,'Performance Data'!$F$2:$F$2540,">=0")),"") -> 0.82270958 | E20: =IFERROR(SUMIFS('Performance Data'!$F$2:$F$2540,'Performance Data'!$B$2:$B$2540,A20)/COUNTIFS('Performance Data'!$B$2:$B$2540,A20,'Performance Data'!$F$2:$F$2540,">=0"),"") -> 0.83208415
A21: 45870 | B21: =IFERROR(IF(AND($B$3="All",$B$4="All"),SUMIFS('Performance Data'!$F$2:$F$2540,'Performance Data'!$B$2:$B$2540,A21)/COUNTIFS('Performance Data'!$B$2:$B$2540,A21,'Performance Data'!$F$2:$F$2540,">=0"),IF($B$3="All",SUMIFS('Performance Data'!$F$2:$F$2540,'Performance Data'!$B$2:$B$2540,A21,'Performance Data'!$H$2:$H$2540,$B$4)/COUNTIFS('Performance Data'!$B$2:$B$2540,A21,'Performance Data'!$H$2:$H$2540,$B$4,'Performance Data'!$F$2:$F$2540,">=0"),IF($B$4="All",SUMIFS('Performance Data'!$F$2:$F$2540,'Performance Data'!$B$2:$B$2540,A21,'Performance Data'!$G$2:$G$2540,$B$3)/COUNTIFS('Performance Data'!$B$2:$B$2540,A21,'Performance Data'!$G$2:$G$2540,$B$3,'Performance Data'!$F$2:$F$2540,">=0"),SUMIFS('Performance Data'!$F$2:$F$2540,'Performance Data'!$B$2:$B$2540,A21,'Performance Data'!$G$2:$G$2540,$B$3,'Performance Data'!$H$2:$H$2540,$B$4)/COUNTIFS('Performance Data'!$B$2:$B$2540,A21,'Performance Data'!$G$2:$G$2540,$B$3,'Performance Data'!$H$2:$H$2540,$B$4,'Performance Data'!$F$2:$F$2540,">=0")))),"") -> 0.68192507 | C21: =IFERROR(IF($B$3="All",SUMIFS('Performance Data'!$F$2:$F$2540,'Performance Data'!$B$2:$B$2540,A21)/COUNTIFS('Performance Data'!$B$2:$B$2540,A21,'Performance Data'!$F$2:$F$2540,">=0"),SUMIFS('Performance Data'!$F$2:$F$2540,'Performance Data'!$B$2:$B$2540,A21,'Performance Data'!$G$2:$G$2540,$B$3)/COUNTIFS('Performance Data'!$B$2:$B$2540,A21,'Performance Data'!$G$2:$G$2540,$B$3,'Performance Data'!$F$2:$F$2540,">=0")),"") -> 0.69405744 | D21: =IFERROR(IF($B$4="All",SUMIFS('Performance Data'!$F$2:$F$2540,'Performance Data'!$B$2:$B$2540,A21)/COUNTIFS('Performance Data'!$B$2:$B$2540,A21,'Performance Data'!$F$2:$F$2540,">=0"),SUMIFS('Performance Data'!$F$2:$F$2540,'Performance Data'!$B$2:$B$2540,A21,'Performance Data'!$H$2:$H$2540,$B$4)/COUNTIFS('Performance Data'!$B$2:$B$2540,A21,'Performance Data'!$H$2:$H$2540,$B$4,'Performance Data'!$F$2:$F$2540,">=0")),"") -> 0.73998421 | E21: =IFERROR(SUMIFS('Performance Data'!$F$2:$F$2540,'Performance Data'!$B$2:$B$2540,A21)/COUNTIFS('Performance Data'!$B$2:$B$2540,A21,'Performance Data'!$F$2:$F$2540,">=0"),"") -> 0.74722374
A22: 45901 | B22: =IFERROR(IF(AND($B$3="All",$B$4="All"),SUMIFS('Performance Data'!$F$2:$F$2540,'Performance Data'!$B$2:$B$2540,A22)/COUNTIFS('Performance Data'!$B$2:$B$2540,A22,'Performance Data'!$F$2:$F$2540,">=0"),IF($B$3="All",SUMIFS('Performance Data'!$F$2:$F$2540,'Performance Data'!$B$2:$B$2540,A22,'Performance Data'!$H$2:$H$2540,$B$4)/COUNTIFS('Performance Data'!$B$2:$B$2540,A22,'Performance Data'!$H$2:$H$2540,$B$4,'Performance Data'!$F$2:$F$2540,">=0"),IF($B$4="All",SUMIFS('Performance Data'!$F$2:$F$2540,'Performance Data'!$B$2:$B$2540,A22,'Performance Data'!$G$2:$G$2540,$B$3)/COUNTIFS('Performance Data'!$B$2:$B$2540,A22,'Performance Data'!$G$2:$G$2540,$B$3,'Performance Data'!$F$2:$F$2540,">=0"),SUMIFS('Performance Data'!$F$2:$F$2540,'Performance Data'!$B$2:$B$2540,A22,'Performance Data'!$G$2:$G$2540,$B$3,'Performance Data'!$H$2:$H$2540,$B$4)/COUNTIFS('Performance Data'!$B$2:$B$2540,A22,'Performance Data'!$G$2:$G$2540,$B$3,'Performance Data'!$H$2:$H$2540,$B$4,'Performance Data'!$F$2:$F$2540,">=0")))),"") -> 0.8239802 | C22: =IFERROR(IF($B$3="All",SUMIFS('Performance Data'!$F$2:$F$2540,'Performance Data'!$B$2:$B$2540,A22)/COUNTIFS('Performance Data'!$B$2:$B$2540,A22,'Performance Data'!$F$2:$F$2540,">=0"),SUMIFS('Performance Data'!$F$2:$F$2540,'Performance Data'!$B$2:$B$2540,A22,'Performance Data'!$G$2:$G$2540,$B$3)/COUNTIFS('Performance Data'!$B$2:$B$2540,A22,'Performance Data'!$G$2:$G$2540,$B$3,'Performance Data'!$F$2:$F$2540,">=0")),"") -> 0.79914676 | D22: =IFERROR(IF($B$4="All",SUMIFS('Performance Data'!$F$2:$F$2540,'Performance Data'!$B$2:$B$2540,A22)/COUNTIFS('Performance Data'!$B$2:$B$2540,A22,'Performance Data'!$F$2:$F$2540,">=0"),SUMIFS('Performance Data'!$F$2:$F$2540,'Performance Data'!$B$2:$B$2540,A22,'Performance Data'!$H$2:$H$2540,$B$4)/COUNTIFS('Performance Data'!$B$2:$B$2540,A22,'Performance Data'!$H$2:$H$2540,$B$4,'Performance Data'!$F$2:$F$2540,">=0")),"") -> 0.84124521 | E22: =IFERROR(SUMIFS('Performance Data'!$F$2:$F$2540,'Performance Data'!$B$2:$B$2540,A22)/COUNTIFS('Performance Data'!$B$2:$B$2540,A22,'Performance Data'!$F$2:$F$2540,">=0"),"") -> 0.84267885
A23: 45931 | B23: =IFERROR(IF(AND($B$3="All",$B$4="All"),SUMIFS('Performance Data'!$F$2:$F$2540,'Performance Data'!$B$2:$B$2540,A23)/COUNTIFS('Performance Data'!$B$2:$B$2540,A23,'Performance Data'!$F$2:$F$2540,">=0"),IF($B$3="All",SUMIFS('Performance Data'!$F$2:$F$2540,'Performance Data'!$B$2:$B$2540,A23,'Performance Data'!$H$2:$H$2540,$B$4)/COUNTIFS('Performance Data'!$B$2:$B$2540,A23,'Performance Data'!$H$2:$H$2540,$B$4,'Performance Data'!$F$2:$F$2540,">=0"),IF($B$4="All",SUMIFS('Performance Data'!$F$2:$F$2540,'Performance Data'!$B$2:$B$2540,A23,'Performance Data'!$G$2:$G$2540,$B$3)/COUNTIFS('Performance Data'!$B$2:$B$2540,A23,'Performance Data'!$G$2:$G$2540,$B$3,'Performance Data'!$F$2:$F$2540,">=0"),SUMIFS('Performance Data'!$F$2:$F$2540,'Performance Data'!$B$2:$B$2540,A23,'Performance Data'!$G$2:$G$2540,$B$3,'Performance Data'!$H$2:$H$2540,$B$4)/COUNTIFS('Performance Data'!$B$2:$B$2540,A23,'Performance Data'!$G$2:$G$2540,$B$3,'Performance Data'!$H$2:$H$2540,$B$4,'Performance Data'!$F$2:$F$2540,">=0")))),"") -> 0.83337759 | C23: =IFERROR(IF($B$3="All",SUMIFS('Performance Data'!$F$2:$F$2540,'Performance Data'!$B$2:$B$2540,A23)/COUNTIFS('Performance Data'!$B$2:$B$2540,A23,'Performance Data'!$F$2:$F$2540,">=0"),SUMIFS('Performance Data'!$F$2:$F$2540,'Performance Data'!$B$2:$B$2540,A23,'Performance Data'!$G$2:$G$2540,$B$3)/COUNTIFS('Performance Data'!$B$2:$B$2540,A23,'Performance Data'!$G$2:$G$2540,$B$3,'Performance Data'!$F$2:$F$2540,">=0")),"") -> 0.84885713 | D23: =IFERROR(IF($B$4="All",SUMIFS('Performance Data'!$F$2:$F$2540,'Performance Data'!$B$2:$B$2540,A23)/COUNTIFS('Performance Data'!$B$2:$B$2540,A23,'Performance Data'!$F$2:$F$2540,">=0"),SUMIFS('Performance Data'!$F$2:$F$2540,'Performance Data'!$B$2:$B$2540,A23,'Performance Data'!$H$2:$H$2540,$B$4)/COUNTIFS('Performance Data'!$B$2:$B$2540,A23,'Performance Data'!$H$2:$H$2540,$B$4,'Performance Data'!$F$2:$F$2540,">=0")),"") -> 0.83130564 | E23: =IFERROR(SUMIFS('Performance Data'!$F$2:$F$2540,'Performance Data'!$B$2:$B$2540,A23)/COUNTIFS('Performance Data'!$B$2:$B$2540,A23,'Performance Data'!$F$2:$F$2540,">=0"),"") -> 0.84247726
A24: 45962 | B24: =IFERROR(IF(AND($B$3="All",$B$4="All"),SUMIFS('Performance Data'!$F$2:$F$2540,'Performance Data'!$B$2:$B$2540,A24)/COUNTIFS('Performance Data'!$B$2:$B$2540,A24,'Performance Data'!$F$2:$F$2540,">=0"),IF($B$3="All",SUMIFS('Performance Data'!$F$2:$F$2540,'Performance Data'!$B$2:$B$2540,A24,'Performance Data'!$H$2:$H$2540,$B$4)/COUNTIFS('Performance Data'!$B$2:$B$2540,A24,'Performance Data'!$H$2:$H$2540,$B$4,'Performance Data'!$F$2:$F$2540,">=0"),IF($B$4="All",SUMIFS('Performance Data'!$F$2:$F$2540,'Performance Data'!$B$2:$B$2540,A24,'Performance Data'!$G$2:$G$2540,$B$3)/COUNTIFS('Performance Data'!$B$2:$B$2540,A24,'Performance Data'!$G$2:$G$2540,$B$3,'Performance Data'!$F$2:$F$2540,">=0"),SUMIFS('Performance Data'!$F$2:$F$2540,'Performance Data'!$B$2:$B$2540,A24,'Performance Data'!$G$2:$G$2540,$B$3,'Performance Data'!$H$2:$H$2540,$B$4)/COUNTIFS('Performance Data'!$B$2:$B$2540,A24,'Performance Data'!$G$2:$G$2540,$B$3,'Performance Data'!$H$2:$H$2540,$B$4,'Performance Data'!$F$2:$F$2540,">=0")))),"") -> 0.81157369 | C24: =IFERROR(IF($B$3="All",SUMIFS('Performance Data'!$F$2:$F$2540,'Performance Data'!$B$2:$B$2540,A24)/COUNTIFS('Performance Data'!$B$2:$B$2540,A24,'Performance Data'!$F$2:$F$2540,">=0"),SUMIFS('Performance Data'!$F$2:$F$2540,'Performance Data'!$B$2:$B$2540,A24,'Performance Data'!$G$2:$G$2540,$B$3)/COUNTIFS('Performance Data'!$B$2:$B$2540,A24,'Performance Data'!$G$2:$G$2540,$B$3,'Performance Data'!$F$2:$F$2540,">=0")),"") -> 0.83976165 | D24: =IFERROR(IF($B$4="All",SUMIFS('Performance Data'!$F$2:$F$2540,'Performance Data'!$B$2:$B$2540,A24)/COUNTIFS('Performance Data'!$B$2:$B$2540,A24,'Performance Data'!$F$2:$F$2540,">=0"),SUMIFS('Performance Data'!$F$2:$F$2540,'Performance Data'!$B$2:$B$2540,A24,'Performance Data'!$H$2:$H$2540,$B$4)/COUNTIFS('Performance Data'!$B$2:$B$2540,A24,'Performance Data'!$H$2:$H$2540,$B$4,'Performance Data'!$F$2:$F$2540,">=0")),"") -> 0.84183397 | E24: =IFERROR(SUMIFS('Performance Data'!$F$2:$F$2540,'Performance Data'!$B$2:$B$2540,A24)/COUNTIFS('Performance Data'!$B$2:$B$2540,A24,'Performance Data'!$F$2:$F$2540,">=0"),"") -> 0.85216422
A25: 45992 | B25: =IFERROR(IF(AND($B$3="All",$B$4="All"),SUMIFS('Performance Data'!$F$2:$F$2540,'Performance Data'!$B$2:$B$2540,A25)/COUNTIFS('Performance Data'!$B$2:$B$2540,A25,'Performance Data'!$F$2:$F$2540,">=0"),IF($B$3="All",SUMIFS('Performance Data'!$F$2:$F$2540,'Performance Data'!$B$2:$B$2540,A25,'Performance Data'!$H$2:$H$2540,$B$4)/COUNTIFS('Performance Data'!$B$2:$B$2540,A25,'Performance Data'!$H$2:$H$2540,$B$4,'Performance Data'!$F$2:$F$2540,">=0"),IF($B$4="All",SUMIFS('Performance Data'!$F$2:$F$2540,'Performance Data'!$B$2:$B$2540,A25,'Performance Data'!$G$2:$G$2540,$B$3)/COUNTIFS('Performance Data'!$B$2:$B$2540,A25,'Performance Data'!$G$2:$G$2540,$B$3,'Performance Data'!$F$2:$F$2540,">=0"),SUMIFS('Performance Data'!$F$2:$F$2540,'Performance Data'!$B$2:$B$2540,A25,'Performance Data'!$G$2:$G$2540,$B$3,'Performance Data'!$H$2:$H$2540,$B$4)/COUNTIFS('Performance Data'!$B$2:$B$2540,A25,'Performance Data'!$G$2:$G$2540,$B$3,'Performance Data'!$H$2:$H$2540,$B$4,'Performance Data'!$F$2:$F$2540,">=0")))),"") -> 0.61082406 | C25: =IFERROR(IF($B$3="All",SUMIFS('Performance Data'!$F$2:$F$2540,'Performance Data'!$B$2:$B$2540,A25)/COUNTIFS('Performance Data'!$B$2:$B$2540,A25,'Performance Data'!$F$2:$F$2540,">=0"),SUMIFS('Performance Data'!$F$2:$F$2540,'Performance Data'!$B$2:$B$2540,A25,'Performance Data'!$G$2:$G$2540,$B$3)/COUNTIFS('Performance Data'!$B$2:$B$2540,A25,'Performance Data'!$G$2:$G$2540,$B$3,'Performance Data'!$F$2:$F$2540,">=0")),"") -> 0.65276838 | D25: =IFERROR(IF($B$4="All",SUMIFS('Performance Data'!$F$2:$F$2540,'Performance Data'!$B$2:$B$2540,A25)/COUNTIFS('Performance Data'!$B$2:$B$2540,A25,'Performance Data'!$F$2:$F$2540,">=0"),SUMIFS('Performance Data'!$F$2:$F$2540,'Performance Data'!$B$2:$B$2540,A25,'Performance Data'!$H$2:$H$2540,$B$4)/COUNTIFS('Performance Data'!$B$2:$B$2540,A25,'Performance Data'!$H$2:$H$2540,$B$4,'Performance Data'!$F$2:$F$2540,">=0")),"") -> 0.67611747 | E25: =IFERROR(SUMIFS('Performance Data'!$F$2:$F$2540,'Performance Data'!$B$2:$B$2540,A25)/COUNTIFS('Performance Data'!$B$2:$B$2540,A25,'Performance Data'!$F$2:$F$2540,">=0"),"") -> 0.7046142
